Workbook

Sheet Tournament Structure
A1: SQUADONE ESPORTS | QUALIFIERS
A3: Correct Match Pattern | D3: Total Group Matchups | E3: 6
A4: A vs B | B4: 6 | D4: Matches per Group Matchup | E4: 6
A5: C vs D | B5: 6 | D5: Total Qualifier Matches | E5: =E3*E4
A6: A vs C | B6: 6
A7: B vs D | B7: 6
A8: A vs D | B8: 6
A9: B vs C | B9: 6

Sheet AvsB_M1
A1: SQUADONE ESPORTS | A vs B | AvsB_M1
A3: # | B3: Team | C3: Total PTS | D3: Placement PTS | E3: Kills | F3: Total DMG | G3: Assists | H3: CQB Kills | I3: LRB Kills | J3: CQB DMG | K3: LRB DMG
A4: 1 | B4: Zero_Hour | C4: 20 | D4: 10 | E4: 10 | F4: 2380.52 | G4: 1 | H4: 9 | I4: 1 | J4: 1371.95 | K4: 1008.57
A5: PLAYER STATISTICS
A6: Player | B6: Kills | C6: Assists | D6: CQB Kills | E6: LRB Kills | F6: CQB DMG | G6: LRB DMG | H6: Total DMG
A7: The--SherLock | B7: 2 | C7: 0 | D7: 1 | E7: 1 | F7: 180.96 | G7: 402.83 | H7: 583.79
A8: GULUzmbi-YT | B8: 1 | C8: 1 | D8: 1 | E8: 0 | F8: 305.44 | G8: 175.4 | H8: 480.84
A9: Granny_In_Bikini | B9: 5 | C9: 0 | D9: 5 | E9: 0 | F9: 532.68 | G9: 257.1 | H9: 789.78
A10: Alien-FPS | B10: 2 | C10: 0 | D10: 2 | E10: 0 | F10: 352.87 | G10: 173.25 | H10: 526.12
A12: 2 | B12: DANJAAR | C12: 13 | D12: 6 | E12: 7 | F12: 2536.51 | G12: 4 | H12: 3 | I12: 4 | J12: 437.77 | K12: 2098.74
A13: PLAYER STATISTICS
A14: Player | B14: Kills | C14: Assists | D14: CQB Kills | E14: LRB Kills | F14: CQB DMG | G14: LRB DMG | H14: Total DMG
A15: WipzY_YT | B15: 1 | C15: 2 | D15: 1 | E15: 0 | F15: 206.88 | G15: 836.08 | H15: 1042.96
A16: BLIND_REBEL | B16: 5 | C16: 1 | D16: 2 | E16: 3 | F16: 186.18 | G16: 561.71 | H16: 747.89
A17: SniperShashi23 | B17: 0 | C17: 1 | D17: 0 | E17: 0 | F17: 23.84 | G17: 319.05 | H17: 342.89
A18: itsooFluFFy | B18: 1 | C18: 0 | D18: 0 | E18: 1 | F18: 20.87 | G18: 381.9 | H18: 402.77
A20: 3 | B20: RAKUZAN | C20: 11 | D20: 4 | E20: 7 | F20: 757.34 | G20: 3 | H20: 5 | I20: 2 | J20: 511.52 | K20: 245.83
A21: PLAYER STATISTICS
A22: Player | B22: Kills | C22: Assists | D22: CQB Kills | E22: LRB Kills | F22: CQB DMG | G22: LRB DMG | H22: Total DMG
A23: 004GlitcH | B23: 1 | C23: 1 | D23: 0 | E23: 1 | F23: 16.99 | G23: 86.93 | H23: 103.92
A24: CR4ZY-XD | B24: 4 | C24: 1 | D24: 4 | E24: 0 | F24: 306.19 | G24: 104.66 | H24: 410.85
A25: AsTRO-OG | B25: 2 | C25: 1 | D25: 1 | E25: 1 | F25: 188.33 | G25: 54.24 | H25: 242.57
A26: LennexCS | B26: 0 | C26: 0 | D26: 0 | E26: 0 | F26: 0 | G26: 0 | H26: 0
A28: 4 | B28: KALI-2 | C28: 5 | D28: 0 | E28: 5 | F28: 920.65 | G28: 2 | H28: 1 | I28: 4 | J28: 461.8 | K28: 458.86
A29: PLAYER STATISTICS
A30: Player | B30: Kills | C30: Assists | D30: CQB Kills | E30: LRB Kills | F30: CQB DMG | G30: LRB DMG | H30: Total DMG
A31: GHOST--404 | B31: 0 | C31: 0 | D31: 0 | E31: 0 | F31: 25.14 | G31: 22.51 | H31: 47.65
A32: hellion_07 | B32: 2 | C32: 2 | D32: 0 | E32: 2 | F32: 205.95 | G32: 237.48 | H32: 443.43
A33: KITHU69 | B33: 3 | C33: 0 | D33: 1 | E33: 2 | F33: 230.7 | G33: 198.86 | H33: 429.56
A35: 5 | B35: Indus Prime | C35: 4 | D35: 1 | E35: 3 | F35: 884.07 | G35: 0 | H35: 2 | I35: 1 | J35: 463.45 | K35: 420.62
A36: PLAYER STATISTICS
A37: Player | B37: Kills | C37: Assists | D37: CQB Kills | E37: LRB Kills | F37: CQB DMG | G37: LRB DMG | H37: Total DMG
A38: Live-With-Addi | B38: 0 | C38: 0 | D38: 0 | E38: 0 | F38: 0 | G38: 104.43 | H38: 104.43
A39: SONARkar98 | B39: 0 | C39: 0 | D39: 0 | E39: 0 | F39: 154.42 | G39: 82.51 | H39: 236.93
A40: Mr_Kol_Gamer | B40: 0 | C40: 0 | D40: 0 | E40: 0 | F40: 100 | G40: 49.61 | H40: 149.61
A41: ReckLess_RV | B41: 3 | C41: 0 | D41: 2 | E41: 1 | F41: 209.04 | G41: 184.07 | H41: 393.11
A43: 6 | B43: SQUAD TWO | C43: 3 | D43: 3 | E43: 0 | F43: 295.8 | G43: 0 | H43: 0 | I43: 0 | J43: 252 | K43: 43.81
A44: PLAYER STATISTICS
A45: Player | B45: Kills | C45: Assists | D45: CQB Kills | E45: LRB Kills | F45: CQB DMG | G45: LRB DMG | H45: Total DMG
A46: D3NZZ0 | B46: 0 | C46: 0 | D46: 0 | E46: 0 | F46: 69.73 | G46: 43.81 | H46: 113.54
...

Sheet AvsB_M2
A1: SQUADONE ESPORTS | A vs B | AvsB_M2
A3: # | B3: Team | C3: Total PTS | D3: Placement PTS | E3: Kills | F3: Total DMG | G3: Assists | H3: CQB Kills | I3: LRB Kills | J3: CQB DMG | K3: LRB DMG
A4: Enter team results above, then place that team's player cards directly underneath.

Sheet AvsB_M3
A1: SQUADONE ESPORTS | A vs B | AvsB_M3
A3: # | B3: Team | C3: Total PTS | D3: Placement PTS | E3: Kills | F3: Total DMG | G3: Assists | H3: CQB Kills | I3: LRB Kills | J3: CQB DMG | K3: LRB DMG
A4: Enter team results above, then place that team's player cards directly underneath.

Sheet AvsB_M4
A1: SQUADONE ESPORTS | A vs B | AvsB_M4
A3: # | B3: Team | C3: Total PTS | D3: Placement PTS | E3: Kills | F3: Total DMG | G3: Assists | H3: CQB Kills | I3: LRB Kills | J3: CQB DMG | K3: LRB DMG
A4: Enter team results above, then place that team's player cards directly underneath.

Sheet AvsB_M5
A1: SQUADONE ESPORTS | A vs B | AvsB_M5
A3: # | B3: Team | C3: Total PTS | D3: Placement PTS | E3: Kills | F3: Total DMG | G3: Assists | H3: CQB Kills | I3: LRB Kills | J3: CQB DMG | K3: LRB DMG
A4: Enter team results above, then place that team's player cards directly underneath.

Sheet AvsB_M6
A1: SQUADONE ESPORTS | A vs B | AvsB_M6
A3: # | B3: Team | C3: Total PTS | D3: Placement PTS | E3: Kills | F3: Total DMG | G3: Assists | H3: CQB Kills | I3: LRB Kills | J3: CQB DMG | K3: LRB DMG
A4: Enter team results above, then place that team's player cards directly underneath.

Sheet CvsD_M1
A1: SQUADONE ESPORTS | C vs D | CvsD_M1
A3: # | B3: Team | C3: Total PTS | D3: Placement PTS | E3: Kills | F3: Total DMG | G3: Assists | H3: CQB Kills | I3: LRB Kills | J3: CQB DMG | K3: LRB DMG
A4: Enter team results above, then place that team's player cards directly underneath.

Sheet CvsD_M2
A1: SQUADONE ESPORTS | C vs D | CvsD_M2
A3: # | B3: Team | C3: Total PTS | D3: Placement PTS | E3: Kills | F3: Total DMG | G3: Assists | H3: CQB Kills | I3: LRB Kills | J3: CQB DMG | K3: LRB DMG
A4: Enter team results above, then place that team's player cards directly underneath.

Sheet CvsD_M3
A1: SQUADONE ESPORTS | C vs D | CvsD_M3
A3: # | B3: Team | C3: Total PTS | D3: Placement PTS | E3: Kills | F3: Total DMG | G3: Assists | H3: CQB Kills | I3: LRB Kills | J3: CQB DMG | K3: LRB DMG
A4: Enter team results above, then place that team's player cards directly underneath.

Sheet CvsD_M4
A1: SQUADONE ESPORTS | C vs D | CvsD_M4
A3: # | B3: Team | C3: Total PTS | D3: Placement PTS | E3: Kills | F3: Total DMG | G3: Assists | H3: CQB Kills | I3: LRB Kills | J3: CQB DMG | K3: LRB DMG
A4: Enter team results above, then place that team's player cards directly underneath.

Sheet CvsD_M5
A1: SQUADONE ESPORTS | C vs D | CvsD_M5
A3: # | B3: Team | C3: Total PTS | D3: Placement PTS | E3: Kills | F3: Total DMG | G3: Assists | H3: CQB Kills | I3: LRB Kills | J3: CQB DMG | K3: LRB DMG
A4: Enter team results above, then place that team's player cards directly underneath.

Sheet CvsD_M6
A1: SQUADONE ESPORTS | C vs D | CvsD_M6
A3: # | B3: Team | C3: Total PTS | D3: Placement PTS | E3: Kills | F3: Total DMG | G3: Assists | H3: CQB Kills | I3: LRB Kills | J3: CQB DMG | K3: LRB DMG
A4: Enter team results above, then place that team's player cards directly underneath.

Sheet AvsC_M1
A1: SQUADONE ESPORTS | A vs C | AvsC_M1
A3: # | B3: Team | C3: Total PTS | D3: Placement PTS | E3: Kills | F3: Total DMG | G3: Assists | H3: CQB Kills | I3: LRB Kills | J3: CQB DMG | K3: LRB DMG
A4: Enter team results above, then place that team's player cards directly underneath.

Sheet AvsC_M2
A1: SQUADONE ESPORTS | A vs C | AvsC_M2
A3: # | B3: Team | C3: Total PTS | D3: Placement PTS | E3: Kills | F3: Total DMG | G3: Assists | H3: CQB Kills | I3: LRB Kills | J3: CQB DMG | K3: LRB DMG
A4: Enter team results above, then place that team's player cards directly underneath.

Sheet AvsC_M3
A1: SQUADONE ESPORTS | A vs C | AvsC_M3
A3: # | B3: Team | C3: Total PTS | D3: Placement PTS | E3: Kills | F3: Total DMG | G3: Assists | H3: CQB Kills | I3: LRB Kills | J3: CQB DMG | K3: LRB DMG
A4: Enter team results above, then place that team's player cards directly underneath.

Sheet AvsC_M4
A1: SQUADONE ESPORTS | A vs C | AvsC_M4
A3: # | B3: Team | C3: Total PTS | D3: Placement PTS | E3: Kills | F3: Total DMG | G3: Assists | H3: CQB Kills | I3: LRB Kills | J3: CQB DMG | K3: LRB DMG
A4: Enter team results above, then place that team's player cards directly underneath.

Sheet AvsC_M5
A1: SQUADONE ESPORTS | A vs C | AvsC_M5
A3: # | B3: Team | C3: Total PTS | D3: Placement PTS | E3: Kills | F3: Total DMG | G3: Assists | H3: CQB Kills | I3: LRB Kills | J3: CQB DMG | K3: LRB DMG
A4: Enter team results above, then place that team's player cards directly underneath.

Sheet AvsC_M6
A1: SQUADONE ESPORTS | A vs C | AvsC_M6
A3: # | B3: Team | C3: Total PTS | D3: Placement PTS | E3: Kills | F3: Total DMG | G3: Assists | H3: CQB Kills | I3: LRB Kills | J3: CQB DMG | K3: LRB DMG
A4: Enter team results above, then place that team's player cards directly underneath.

Sheet BvsD_M1
A1: SQUADONE ESPORTS | B vs D | BvsD_M1
A3: # | B3: Team | C3: Total PTS | D3: Placement PTS | E3: Kills | F3: Total DMG | G3: Assists | H3: CQB Kills | I3: LRB Kills | J3: CQB DMG | K3: LRB DMG
A4: Enter team results above, then place that team's player cards directly underneath.

Sheet BvsD_M2
A1: SQUADONE ESPORTS | B vs D | BvsD_M2
A3: # | B3: Team | C3: Total PTS | D3: Placement PTS | E3: Kills | F3: Total DMG | G3: Assists | H3: CQB Kills | I3: LRB Kills | J3: CQB DMG | K3: LRB DMG
A4: Enter team results above, then place that team's player cards directly underneath.

Sheet BvsD_M3
A1: SQUADONE ESPORTS | B vs D | BvsD_M3
A3: # | B3: Team | C3: Total PTS | D3: Placement PTS | E3: Kills | F3: Total DMG | G3: Assists | H3: CQB Kills | I3: LRB Kills | J3: CQB DMG | K3: LRB DMG
A4: Enter team results above, then place that team's player cards directly underneath.

Sheet BvsD_M4
A1: SQUADONE ESPORTS | B vs D | BvsD_M4
A3: # | B3: Team | C3: Total PTS | D3: Placement PTS | E3: Kills | F3: Total DMG | G3: Assists | H3: CQB Kills | I3: LRB Kills | J3: CQB DMG | K3: LRB DMG
A4: Enter team results above, then place that team's player cards directly underneath.

Sheet BvsD_M5
A1: SQUADONE ESPORTS | B vs D | BvsD_M5
A3: # | B3: Team | C3: Total PTS | D3: Placement PTS | E3: Kills | F3: Total DMG | G3: Assists | H3: CQB Kills | I3: LRB Kills | J3: CQB DMG | K3: LRB DMG
A4: Enter team results above, then place that team's player cards directly underneath.

Sheet BvsD_M6
A1: SQUADONE ESPORTS | B vs D | BvsD_M6
A3: # | B3: Team | C3: Total PTS | D3: Placement PTS | E3: Kills | F3: Total DMG | G3: Assists | H3: CQB Kills | I3: LRB Kills | J3: CQB DMG | K3: LRB DMG
A4: Enter team results above, then place that team's player cards directly underneath.

Sheet AvsD_M1
A1: SQUADONE ESPORTS | A vs D | AvsD_M1
A3: # | B3: Team | C3: Total PTS | D3: Placement PTS | E3: Kills | F3: Total DMG | G3: Assists | H3: CQB Kills | I3: LRB Kills | J3: CQB DMG | K3: LRB DMG
A4: Enter team results above, then place that team's player cards directly underneath.

Sheet AvsD_M2
A1: SQUADONE ESPORTS | A vs D | AvsD_M2
A3: # | B3: Team | C3: Total PTS | D3: Placement PTS | E3: Kills | F3: Total DMG | G3: Assists | H3: CQB Kills | I3: LRB Kills | J3: CQB DMG | K3: LRB DMG
A4: Enter team results above, then place that team's player cards directly underneath.

Sheet AvsD_M3
A1: SQUADONE ESPORTS | A vs D | AvsD_M3
A3: # | B3: Team | C3: Total PTS | D3: Placement PTS | E3: Kills | F3: Total DMG | G3: Assists | H3: CQB Kills | I3: LRB Kills | J3: CQB DMG | K3: LRB DMG
A4: Enter team results above, then place that team's player cards directly underneath.

Sheet AvsD_M4
A1: SQUADONE ESPORTS | A vs D | AvsD_M4
A3: # | B3: Team | C3: Total PTS | D3: Placement PTS | E3: Kills | F3: Total DMG | G3: Assists | H3: CQB Kills | I3: LRB Kills | J3: CQB DMG | K3: LRB DMG
A4: Enter team results above, then place that team's player cards directly underneath.

Sheet AvsD_M5
A1: SQUADONE ESPORTS | A vs D | AvsD_M5
A3: # | B3: Team | C3: Total PTS | D3: Placement PTS | E3: Kills | F3: Total DMG | G3: Assists | H3: CQB Kills | I3: LRB Kills | J3: CQB DMG | K3: LRB DMG
A4: Enter team results above, then place that team's player cards directly underneath.

Sheet AvsD_M6
A1: SQUADONE ESPORTS | A vs D | AvsD_M6
A3: # | B3: Team | C3: Total PTS | D3: Placement PTS | E3: Kills | F3: Total DMG | G3: Assists | H3: CQB Kills | I3: LRB Kills | J3: CQB DMG | K3: LRB DMG
A4: Enter team results above, then place that team's player cards directly underneath.

Sheet BvsC_M1
A1: SQUADONE ESPORTS | B vs C | BvsC_M1
A3: # | B3: Team | C3: Total PTS | D3: Placement PTS | E3: Kills | F3: Total DMG | G3: Assists | H3: CQB Kills | I3: LRB Kills | J3: CQB DMG | K3: LRB DMG
A4: Enter team results above, then place that team's player cards directly underneath.

Sheet BvsC_M2
A1: SQUADONE ESPORTS | B vs C | BvsC_M2
A3: # | B3: Team | C3: Total PTS | D3: Placement PTS | E3: Kills | F3: Total DMG | G3: Assists | H3: CQB Kills | I3: LRB Kills | J3: CQB DMG | K3: LRB DMG
A4: Enter team results above, then place that team's player cards directly underneath.

Sheet BvsC_M3
A1: SQUADONE ESPORTS | B vs C | BvsC_M3
A3: # | B3: Team | C3: Total PTS | D3: Placement PTS | E3: Kills | F3: Total DMG | G3: Assists | H3: CQB Kills | I3: LRB Kills | J3: CQB DMG | K3: LRB DMG
A4: Enter team results above, then place that team's player cards directly underneath.

Sheet BvsC_M4
A1: SQUADONE ESPORTS | B vs C | BvsC_M4
A3: # | B3: Team | C3: Total PTS | D3: Placement PTS | E3: Kills | F3: Total DMG | G3: Assists | H3: CQB Kills | I3: LRB Kills | J3: CQB DMG | K3: LRB DMG
A4: Enter team results above, then place that team's player cards directly underneath.

Sheet BvsC_M5
A1: SQUADONE ESPORTS | B vs C | BvsC_M5
A3: # | B3: Team | C3: Total PTS | D3: Placement PTS | E3: Kills | F3: Total DMG | G3: Assists | H3: CQB Kills | I3: LRB Kills | J3: CQB DMG | K3: LRB DMG
A4: Enter team results above, then place that team's player cards directly underneath.

Sheet BvsC_M6
A1: SQUADONE ESPORTS | B vs C | BvsC_M6
A3: # | B3: Team | C3: Total PTS | D3: Placement PTS | E3: Kills | F3: Total DMG | G3: Assists | H3: CQB Kills | I3: LRB Kills | J3: CQB DMG | K3: LRB DMG
A4: Enter team results above, then place that team's player cards directly underneath.

Sheet Overall Leaderboard
A1: OVERALL QUALIFIERS LEADERBOARD
A3: Rank | B3: Team | C3: Matches | D3: Total PTS | E3: Placement PTS | F3: Kills | G3: Total DMG | H3: Assists | I3: CQB Kills | J3: LRB Kills
A4: 1 | B4: A047 | C4: =COUNTIF('AvsB_M1'!$B$4:$B$100,B4)+COUNTIF('AvsB_M2'!$B$4:$B$100,B4)+COUNTIF('AvsB_M3'!$B$4:$B$100,B4)+COUNTIF('AvsB_M4'!$B$4:$B$100,B4)+COUNTIF('AvsB_M5'!$B$4:$B$100,B4)+COUNTIF('AvsB_M6'!$B$4:$B$100,B4)+COUNTIF('CvsD_M1'!$B$4:$B$100,B4)+COUNTIF('CvsD_M2'!$B$4:$B$100,B4)+COUNTIF('CvsD_M3'!$B$4:$B$100,B4)+COUNTIF('CvsD_M4'!$B$4:$B$100,B4)+COUNTIF('CvsD_M5'!$B$4:$B$100,B4)+COUNTIF('CvsD_M6'!$B$4:$B$100,B4)+COUNTIF('AvsC_M1'!$B$4:$B$100,B4)+COUNTIF('AvsC_M2'!$B$4:$B$100,B4)+COUNTIF('AvsC_M3'!$B$4:$B$100,B4)+COUNTIF('AvsC_M4'!$B$4:$B$100,B4)+COUNTIF('AvsC_M5'!$B$4:$B$100,B4)+COUNTIF('AvsC_M6'!$B$4:$B$100,B4)+COUNTIF('BvsD_M1'!$B$4:$B$100,B4)+COUNTIF('BvsD_M2'!$B$4:$B$100,B4)+COUNTIF('BvsD_M3'!$B$4:$B$100,B4)+COUNTIF('BvsD_M4'!$B$4:$B$100,B4)+COUNTIF('BvsD_M5'!$B$4:$B$100,B4)+COUNTIF('BvsD_M6'!$B$4:$B$100,B4)+COUNTIF('AvsD_M1'!$B$4:$B$100,B4)+COUNTIF('AvsD_M2'!$B$4:$B$100,B4)+COUNTIF('AvsD_M3'!$B$4:$B$100,B4)+COUNTIF('AvsD_M4'!$B$4:$B$100,B4)+COUNTIF('AvsD_M5'!$B$4:$B$100,B4)+COUNTIF('AvsD_M6'!$B$4:$B$100,B4)+COUNTIF('BvsC_M1'!$B$4:$B$100,B4)+COUNTIF('BvsC_M2'!$B$4:$B$100,B4)+COUNTIF('BvsC_M3'!$B$4:$B$100,B4)+COUNTIF('BvsC_M4'!$B$4:$B$100,B4)+COUNTIF('BvsC_M5'!$B$4:$B$100,B4)+COUNTIF('BvsC_M6'!$B$4:$B$100,B4) | D4: =SUMIF('AvsB_M1'!$B$4:$B$100,B4,'AvsB_M1'!$C$4:$C$100)+SUMIF('AvsB_M2'!$B$4:$B$100,B4,'AvsB_M2'!$C$4:$C$100)+SUMIF('AvsB_M3'!$B$4:$B$100,B4,'AvsB_M3'!$C$4:$C$100)+SUMIF('AvsB_M4'!$B$4:$B$100,B4,'AvsB_M4'!$C$4:$C$100)+SUMIF('AvsB_M5'!$B$4:$B$100,B4,'AvsB_M5'!$C$4:$C$100)+SUMIF('AvsB_M6'!$B$4:$B$100,B4,'AvsB_M6'!$C$4:$C$100)+SUMIF('CvsD_M1'!$B$4:$B$100,B4,'CvsD_M1'!$C$4:$C$100)+SUMIF('CvsD_M2'!$B$4:$B$100,B4,'CvsD_M2'!$C$4:$C$100)+SUMIF('CvsD_M3'!$B$4:$B$100,B4,'CvsD_M3'!$C$4:$C$100)+SUMIF('CvsD_M4'!$B$4:$B$100,B4,'CvsD_M4'!$C$4:$C$100)+SUMIF('CvsD_M5'!$B$4:$B$100,B4,'CvsD_M5'!$C$4:$C$100)+SUMIF('CvsD_M6'!$B$4:$B$100,B4,'CvsD_M6'!$C$4:$C$100)+SUMIF('AvsC_M1'!$B$4:$B$100,B4,'AvsC_M1'!$C$4:$C$100)+SUMIF('AvsC_M2'!$B$4:$B$100,B4,'AvsC_M2'!$C$4:$C$100)+SUMIF('AvsC_M3'!$B$4:$B$100,B4,'AvsC_M3'!$C$4:$C$100)+SUMIF('AvsC_M4'!$B$4:$B$100,B4,'AvsC_M4'!$C$4:$C$100)+SUMIF('AvsC_M5'!$B$4:$B$100,B4,'AvsC_M5'!$C$4:$C$100)+SUMIF('AvsC_M6'!$B$4:$B$100,B4,'AvsC_M6'!$C$4:$C$100)+SUMIF('BvsD_M1'!$B$4:$B$100,B4,'BvsD_M1'!$C$4:$C$100)+SUMIF('BvsD_M2'!$B$4:$B$100,B4,'BvsD_M2'!$C$4:$C$100)+SUMIF('BvsD_M3'!$B$4:$B$100,B4,'BvsD_M3'!$C$4:$C$100)+SUMIF('BvsD_M4'!$B$4:$B$100,B4,'BvsD_M4'!$C$4:$C$100)+SUMIF('BvsD_M5'!$B$4:$B$100,B4,'BvsD_M5'!$C$4:$C$100)+SUMIF('BvsD_M6'!$B$4:$B$100,B4,'BvsD_M6'!$C$4:$C$100)+SUMIF('AvsD_M1'!$B$4:$B$100,B4,'AvsD_M1'!$C$4:$C$100)+SUMIF('AvsD_M2'!$B$4:$B$100,B4,'AvsD_M2'!$C$4:$C$100)+SUMIF('AvsD_M3'!$B$4:$B$100,B4,'AvsD_M3'!$C$4:$C$100)+SUMIF('AvsD_M4'!$B$4:$B$100,B4,'AvsD_M4'!$C$4:$C$100)+SUMIF('AvsD_M5'!$B$4:$B$100,B4,'AvsD_M5'!$C$4:$C$100)+SUMIF('AvsD_M6'!$B$4:$B$100,B4,'AvsD_M6'!$C$4:$C$100)+SUMIF('BvsC_M1'!$B$4:$B$100,B4,'BvsC_M1'!$C$4:$C$100)+SUMIF('BvsC_M2'!$B$4:$B$100,B4,'BvsC_M2'!$C$4:$C$100)+SUMIF('BvsC_M3'!$B$4:$B$100,B4,'BvsC_M3'!$C$4:$C$100)+SUMIF('BvsC_M4'!$B$4:$B$100,B4,'BvsC_M4'!$C$4:$C$100)+SUMIF('BvsC_M5'!$B$4:$B$100,B4,'BvsC_M5'!$C$4:$C$100)+SUMIF('BvsC_M6'!$B$4:$B$100,B4,'BvsC_M6'!$C$4:$C$100) | E4: =SUMIF('AvsB_M1'!$B$4:$B$100,B4,'AvsB_M1'!$D$4:$D$100)+SUMIF('AvsB_M2'!$B$4:$B$100,B4,'AvsB_M2'!$D$4:$D$100)+SUMIF('AvsB_M3'!$B$4:$B$100,B4,'AvsB_M3'!$D$4:$D$100)+SUMIF('AvsB_M4'!$B$4:$B$100,B4,'AvsB_M4'!$D$4:$D$100)+SUMIF('AvsB_M5'!$B$4:$B$100,B4,'AvsB_M5'!$D$4:$D$100)+SUMIF('AvsB_M6'!$B$4:$B$100,B4,'AvsB_M6'!$D$4:$D$100)+SUMIF('CvsD_M1'!$B$4:$B$100,B4,'CvsD_M1'!$D$4:$D$100)+SUMIF('CvsD_M2'!$B$4:$B$100,B4,'CvsD_M2'!$D$4:$D$100)+SUMIF('CvsD_M3'!$B$4:$B$100,B4,'CvsD_M3'!$D$4:$D$100)+SUMIF('CvsD_M4'!$B$4:$B$100,B4,'CvsD_M4'!$D$4:$D$100)+SUMIF('CvsD_M5'!$B$4:$B$100,B4,'CvsD_M5'!$D$4:$D$100)+SUMIF('CvsD_M6'!$B$4:$B$100,B4,'CvsD_M6'!$D$4:$D$100)+SUMIF('AvsC_M1'!$B$4:$B$100,B4,'AvsC_M1'!$D$4:$D$100)+SUMIF('AvsC_M2'!$B$4:$B$100,B4,'AvsC_M2'!$D$4:$D$100)+SUMIF('AvsC_M3'!$B$4:$B$100,B4,'AvsC_M3'!$D$4:$D$100)+SUMIF('AvsC_M4'!$B$4:$B$100,B4,'AvsC_M4'!$D$4:$D$100)+SUMIF('AvsC_M5'!$B$4:$B$100,B4,'AvsC_M5'!$D$4:$D$100)+SUMIF('AvsC_M6'!$B$4:$B$100,B4,'AvsC_M6'!$D$4:$D$100)+SUMIF('BvsD_M1'!$B$4:$B$100,B4,'BvsD_M1'!$D$4:$D$100)+SUMIF('BvsD_M2'!$B$4:$B$100,B4,'BvsD_M2'!$D$4:$D$100)+SUMIF('BvsD_M3'!$B$4:$B$100,B4,'BvsD_M3'!$D$4:$D$100)+SUMIF('BvsD_M4'!$B$4:$B$100,B4,'BvsD_M4'!$D$4:$D$100)+SUMIF('BvsD_M5'!$B$4:$B$100,B4,'BvsD_M5'!$D$4:$D$100)+SUMIF('BvsD_M6'!$B$4:$B$100,B4,'BvsD_M6'!$D$4:$D$100)+SUMIF('AvsD_M1'!$B$4:$B$100,B4,'AvsD_M1'!$D$4:$D$100)+SUMIF('AvsD_M2'!$B$4:$B$100,B4,'AvsD_M2'!$D$4:$D$100)+SUMIF('AvsD_M3'!$B$4:$B$100,B4,'AvsD_M3'!$D$4:$D$100)+SUMIF('AvsD_M4'!$B$4:$B$100,B4,'AvsD_M4'!$D$4:$D$100)+SUMIF('AvsD_M5'!$B$4:$B$100,B4,'AvsD_M5'!$D$4:$D$100)+SUMIF('AvsD_M6'!$B$4:$B$100,B4,'AvsD_M6'!$D$4:$D$100)+SUMIF('BvsC_M1'!$B$4:$B$100,B4,'BvsC_M1'!$D$4:$D$100)+SUMIF('BvsC_M2'!$B$4:$B$100,B4,'BvsC_M2'!$D$4:$D$100)+SUMIF('BvsC_M3'!$B$4:$B$100,B4,'BvsC_M3'!$D$4:$D$100)+SUMIF('BvsC_M4'!$B$4:$B$100,B4,'BvsC_M4'!$D$4:$D$100)+SUMIF('BvsC_M5'!$B$4:$B$100,B4,'BvsC_M5'!$D$4:$D$100)+SUMIF('BvsC_M6'!$B$4:$B$100,B4,'BvsC_M6'!$D$4:$D$100) | F4: =SUMIF('AvsB_M1'!$B$4:$B$100,B4,'AvsB_M1'!$E$4:$E$100)+SUMIF('AvsB_M2'!$B$4:$B$100,B4,'AvsB_M2'!$E$4:$E$100)+SUMIF('AvsB_M3'!$B$4:$B$100,B4,'AvsB_M3'!$E$4:$E$100)+SUMIF('AvsB_M4'!$B$4:$B$100,B4,'AvsB_M4'!$E$4:$E$100)+SUMIF('AvsB_M5'!$B$4:$B$100,B4,'AvsB_M5'!$E$4:$E$100)+SUMIF('AvsB_M6'!$B$4:$B$100,B4,'AvsB_M6'!$E$4:$E$100)+SUMIF('CvsD_M1'!$B$4:$B$100,B4,'CvsD_M1'!$E$4:$E$100)+SUMIF('CvsD_M2'!$B$4:$B$100,B4,'CvsD_M2'!$E$4:$E$100)+SUMIF('CvsD_M3'!$B$4:$B$100,B4,'CvsD_M3'!$E$4:$E$100)+SUMIF('CvsD_M4'!$B$4:$B$100,B4,'CvsD_M4'!$E$4:$E$100)+SUMIF('CvsD_M5'!$B$4:$B$100,B4,'CvsD_M5'!$E$4:$E$100)+SUMIF('CvsD_M6'!$B$4:$B$100,B4,'CvsD_M6'!$E$4:$E$100)+SUMIF('AvsC_M1'!$B$4:$B$100,B4,'AvsC_M1'!$E$4:$E$100)+SUMIF('AvsC_M2'!$B$4:$B$100,B4,'AvsC_M2'!$E$4:$E$100)+SUMIF('AvsC_M3'!$B$4:$B$100,B4,'AvsC_M3'!$E$4:$E$100)+SUMIF('AvsC_M4'!$B$4:$B$100,B4,'AvsC_M4'!$E$4:$E$100)+SUMIF('AvsC_M5'!$B$4:$B$100,B4,'AvsC_M5'!$E$4:$E$100)+SUMIF('AvsC_M6'!$B$4:$B$100,B4,'AvsC_M6'!$E$4:$E$100)+SUMIF('BvsD_M1'!$B$4:$B$100,B4,'BvsD_M1'!$E$4:$E$100)+SUMIF('BvsD_M2'!$B$4:$B$100,B4,'BvsD_M2'!$E$4:$E$100)+SUMIF('BvsD_M3'!$B$4:$B$100,B4,'BvsD_M3'!$E$4:$E$100)+SUMIF('BvsD_M4'!$B$4:$B$100,B4,'BvsD_M4'!$E$4:$E$100)+SUMIF('BvsD_M5'!$B$4:$B$100,B4,'BvsD_M5'!$E$4:$E$100)+SUMIF('BvsD_M6'!$B$4:$B$100,B4,'BvsD_M6'!$E$4:$E$100)+SUMIF('AvsD_M1'!$B$4:$B$100,B4,'AvsD_M1'!$E$4:$E$100)+SUMIF('AvsD_M2'!$B$4:$B$100,B4,'AvsD_M2'!$E$4:$E$100)+SUMIF('AvsD_M3'!$B$4:$B$100,B4,'AvsD_M3'!$E$4:$E$100)+SUMIF('AvsD_M4'!$B$4:$B$100,B4,'AvsD_M4'!$E$4:$E$100)+SUMIF('AvsD_M5'!$B$4:$B$100,B4,'AvsD_M5'!$E$4:$E$100)+SUMIF('AvsD_M6'!$B$4:$B$100,B4,'AvsD_M6'!$E$4:$E$100)+SUMIF('BvsC_M1'!$B$4:$B$100,B4,'BvsC_M1'!$E$4:$E$100)+SUMIF('BvsC_M2'!$B$4:$B$100,B4,'BvsC_M2'!$E$4:$E$100)+SUMIF('BvsC_M3'!$B$4:$B$100,B4,'BvsC_M3'!$E$4:$E$100)+SUMIF('BvsC_M4'!$B$4:$B$100,B4,'BvsC_M4'!$E$4:$E$100)+SUMIF('BvsC_M5'!$B$4:$B$100,B4,'BvsC_M5'!$E$4:$E$100)+SUMIF('BvsC_M6'!$B$4:$B$100,B4,'BvsC_M6'!$E$4:$E$100) | G4: =SUMIF('AvsB_M1'!$B$4:$B$100,B4,'AvsB_M1'!$F$4:$F$100)+SUMIF('AvsB_M2'!$B$4:$B$100,B4,'AvsB_M2'!$F$4:$F$100)+SUMIF('AvsB_M3'!$B$4:$B$100,B4,'AvsB_M3'!$F$4:$F$100)+SUMIF('AvsB_M4'!$B$4:$B$100,B4,'AvsB_M4'!$F$4:$F$100)+SUMIF('AvsB_M5'!$B$4:$B$100,B4,'AvsB_M5'!$F$4:$F$100)+SUMIF('AvsB_M6'!$B$4:$B$100,B4,'AvsB_M6'!$F$4:$F$100)+SUMIF('CvsD_M1'!$B$4:$B$100,B4,'CvsD_M1'!$F$4:$F$100)+SUMIF('CvsD_M2'!$B$4:$B$100,B4,'CvsD_M2'!$F$4:$F$100)+SUMIF('CvsD_M3'!$B$4:$B$100,B4,'CvsD_M3'!$F$4:$F$100)+SUMIF('CvsD_M4'!$B$4:$B$100,B4,'CvsD_M4'!$F$4:$F$100)+SUMIF('CvsD_M5'!$B$4:$B$100,B4,'CvsD_M5'!$F$4:$F$100)+SUMIF('CvsD_M6'!$B$4:$B$100,B4,'CvsD_M6'!$F$4:$F$100)+SUMIF('AvsC_M1'!$B$4:$B$100,B4,'AvsC_M1'!$F$4:$F$100)+SUMIF('AvsC_M2'!$B$4:$B$100,B4,'AvsC_M2'!$F$4:$F$100)+SUMIF('AvsC_M3'!$B$4:$B$100,B4,'AvsC_M3'!$F$4:$F$100)+SUMIF('AvsC_M4'!$B$4:$B$100,B4,'AvsC_M4'!$F$4:$F$100)+SUMIF('AvsC_M5'!$B$4:$B$100,B4,'AvsC_M5'!$F$4:$F$100)+SUMIF('AvsC_M6'!$B$4:$B$100,B4,'AvsC_M6'!$F$4:$F$100)+SUMIF('BvsD_M1'!$B$4:$B$100,B4,'BvsD_M1'!$F$4:$F$100)+SUMIF('BvsD_M2'!$B$4:$B$100,B4,'BvsD_M2'!$F$4:$F$100)+SUMIF('BvsD_M3'!$B$4:$B$100,B4,'BvsD_M3'!$F$4:$F$100)+SUMIF('BvsD_M4'!$B$4:$B$100,B4,'BvsD_M4'!$F$4:$F$100)+SUMIF('BvsD_M5'!$B$4:$B$100,B4,'BvsD_M5'!$F$4:$F$100)+SUMIF('BvsD_M6'!$B$4:$B$100,B4,'BvsD_M6'!$F$4:$F$100)+SUMIF('AvsD_M1'!$B$4:$B$100,B4,'AvsD_M1'!$F$4:$F$100)+SUMIF('AvsD_M2'!$B$4:$B$100,B4,'AvsD_M2'!$F$4:$F$100)+SUMIF('AvsD_M3'!$B$4:$B$100,B4,'AvsD_M3'!$F$4:$F$100)+SUMIF('AvsD_M4'!$B$4:$B$100,B4,'AvsD_M4'!$F$4:$F$100)+SUMIF('AvsD_M5'!$B$4:$B$100,B4,'AvsD_M5'!$F$4:$F$100)+SUMIF('AvsD_M6'!$B$4:$B$100,B4,'AvsD_M6'!$F$4:$F$100)+SUMIF('BvsC_M1'!$B$4:$B$100,B4,'BvsC_M1'!$F$4:$F$100)+SUMIF('BvsC_M2'!$B$4:$B$100,B4,'BvsC_M2'!$F$4:$F$100)+SUMIF('BvsC_M3'!$B$4:$B$100,B4,'BvsC_M3'!$F$4:$F$100)+SUMIF('BvsC_M4'!$B$4:$B$100,B4,'BvsC_M4'!$F$4:$F$100)+SUMIF('BvsC_M5'!$B$4:$B$100,B4,'BvsC_M5'!$F$4:$F$100)+SUMIF('BvsC_M6'!$B$4:$B$100,B4,'BvsC_M6'!$F$4:$F$100) | H4: =SUMIF('AvsB_M1'!$B$4:$B$100,B4,'AvsB_M1'!$G$4:$G$100)+SUMIF('AvsB_M2'!$B$4:$B$100,B4,'AvsB_M2'!$G$4:$G$100)+SUMIF('AvsB_M3'!$B$4:$B$100,B4,'AvsB_M3'!$G$4:$G$100)+SUMIF('AvsB_M4'!$B$4:$B$100,B4,'AvsB_M4'!$G$4:$G$100)+SUMIF('AvsB_M5'!$B$4:$B$100,B4,'AvsB_M5'!$G$4:$G$100)+SUMIF('AvsB_M6'!$B$4:$B$100,B4,'AvsB_M6'!$G$4:$G$100)+SUMIF('CvsD_M1'!$B$4:$B$100,B4,'CvsD_M1'!$G$4:$G$100)+SUMIF('CvsD_M2'!$B$4:$B$100,B4,'CvsD_M2'!$G$4:$G$100)+SUMIF('CvsD_M3'!$B$4:$B$100,B4,'CvsD_M3'!$G$4:$G$100)+SUMIF('CvsD_M4'!$B$4:$B$100,B4,'CvsD_M4'!$G$4:$G$100)+SUMIF('CvsD_M5'!$B$4:$B$100,B4,'CvsD_M5'!$G$4:$G$100)+SUMIF('CvsD_M6'!$B$4:$B$100,B4,'CvsD_M6'!$G$4:$G$100)+SUMIF('AvsC_M1'!$B$4:$B$100,B4,'AvsC_M1'!$G$4:$G$100)+SUMIF('AvsC_M2'!$B$4:$B$100,B4,'AvsC_M2'!$G$4:$G$100)+SUMIF('AvsC_M3'!$B$4:$B$100,B4,'AvsC_M3'!$G$4:$G$100)+SUMIF('AvsC_M4'!$B$4:$B$100,B4,'AvsC_M4'!$G$4:$G$100)+SUMIF('AvsC_M5'!$B$4:$B$100,B4,'AvsC_M5'!$G$4:$G$100)+SUMIF('AvsC_M6'!$B$4:$B$100,B4,'AvsC_M6'!$G$4:$G$100)+SUMIF('BvsD_M1'!$B$4:$B$100,B4,'BvsD_M1'!$G$4:$G$100)+SUMIF('BvsD_M2'!$B$4:$B$100,B4,'BvsD_M2'!$G$4:$G$100)+SUMIF('BvsD_M3'!$B$4:$B$100,B4,'BvsD_M3'!$G$4:$G$100)+SUMIF('BvsD_M4'!$B$4:$B$100,B4,'BvsD_M4'!$G$4:$G$100)+SUMIF('BvsD_M5'!$B$4:$B$100,B4,'BvsD_M5'!$G$4:$G$100)+SUMIF('BvsD_M6'!$B$4:$B$100,B4,'BvsD_M6'!$G$4:$G$100)+SUMIF('AvsD_M1'!$B$4:$B$100,B4,'AvsD_M1'!$G$4:$G$100)+SUMIF('AvsD_M2'!$B$4:$B$100,B4,'AvsD_M2'!$G$4:$G$100)+SUMIF('AvsD_M3'!$B$4:$B$100,B4,'AvsD_M3'!$G$4:$G$100)+SUMIF('AvsD_M4'!$B$4:$B$100,B4,'AvsD_M4'!$G$4:$G$100)+SUMIF('AvsD_M5'!$B$4:$B$100,B4,'AvsD_M5'!$G$4:$G$100)+SUMIF('AvsD_M6'!$B$4:$B$100,B4,'AvsD_M6'!$G$4:$G$100)+SUMIF('BvsC_M1'!$B$4:$B$100,B4,'BvsC_M1'!$G$4:$G$100)+SUMIF('BvsC_M2'!$B$4:$B$100,B4,'BvsC_M2'!$G$4:$G$100)+SUMIF('BvsC_M3'!$B$4:$B$100,B4,'BvsC_M3'!$G$4:$G$100)+SUMIF('BvsC_M4'!$B$4:$B$100,B4,'BvsC_M4'!$G$4:$G$100)+SUMIF('BvsC_M5'!$B$4:$B$100,B4,'BvsC_M5'!$G$4:$G$100)+SUMIF('BvsC_M6'!$B$4:$B$100,B4,'BvsC_M6'!$G$4:$G$100) | I4: =SUMIF('AvsB_M1'!$B$4:$B$100,B4,'AvsB_M1'!$H$4:$H$100)+SUMIF('AvsB_M2'!$B$4:$B$100,B4,'AvsB_M2'!$H$4:$H$100)+SUMIF('AvsB_M3'!$B$4:$B$100,B4,'AvsB_M3'!$H$4:$H$100)+SUMIF('AvsB_M4'!$B$4:$B$100,B4,'AvsB_M4'!$H$4:$H$100)+SUMIF('AvsB_M5'!$B$4:$B$100,B4,'AvsB_M5'!$H$4:$H$100)+SUMIF('AvsB_M6'!$B$4:$B$100,B4,'AvsB_M6'!$H$4:$H$100)+SUMIF('CvsD_M1'!$B$4:$B$100,B4,'CvsD_M1'!$H$4:$H$100)+SUMIF('CvsD_M2'!$B$4:$B$100,B4,'CvsD_M2'!$H$4:$H$100)+SUMIF('CvsD_M3'!$B$4:$B$100,B4,'CvsD_M3'!$H$4:$H$100)+SUMIF('CvsD_M4'!$B$4:$B$100,B4,'CvsD_M4'!$H$4:$H$100)+SUMIF('CvsD_M5'!$B$4:$B$100,B4,'CvsD_M5'!$H$4:$H$100)+SUMIF('CvsD_M6'!$B$4:$B$100,B4,'CvsD_M6'!$H$4:$H$100)+SUMIF('AvsC_M1'!$B$4:$B$100,B4,'AvsC_M1'!$H$4:$H$100)+SUMIF('AvsC_M2'!$B$4:$B$100,B4,'AvsC_M2'!$H$4:$H$100)+SUMIF('AvsC_M3'!$B$4:$B$100,B4,'AvsC_M3'!$H$4:$H$100)+SUMIF('AvsC_M4'!$B$4:$B$100,B4,'AvsC_M4'!$H$4:$H$100)+SUMIF('AvsC_M5'!$B$4:$B$100,B4,'AvsC_M5'!$H$4:$H$100)+SUMIF('AvsC_M6'!$B$4:$B$100,B4,'AvsC_M6'!$H$4:$H$100)+SUMIF('BvsD_M1'!$B$4:$B$100,B4,'BvsD_M1'!$H$4:$H$100)+SUMIF('BvsD_M2'!$B$4:$B$100,B4,'BvsD_M2'!$H$4:$H$100)+SUMIF('BvsD_M3'!$B$4:$B$100,B4,'BvsD_M3'!$H$4:$H$100)+SUMIF('BvsD_M4'!$B$4:$B$100,B4,'BvsD_M4'!$H$4:$H$100)+SUMIF('BvsD_M5'!$B$4:$B$100,B4,'BvsD_M5'!$H$4:$H$100)+SUMIF('BvsD_M6'!$B$4:$B$100,B4,'BvsD_M6'!$H$4:$H$100)+SUMIF('AvsD_M1'!$B$4:$B$100,B4,'AvsD_M1'!$H$4:$H$100)+SUMIF('AvsD_M2'!$B$4:$B$100,B4,'AvsD_M2'!$H$4:$H$100)+SUMIF('AvsD_M3'!$B$4:$B$100,B4,'AvsD_M3'!$H$4:$H$100)+SUMIF('AvsD_M4'!$B$4:$B$100,B4,'AvsD_M4'!$H$4:$H$100)+SUMIF('AvsD_M5'!$B$4:$B$100,B4,'AvsD_M5'!$H$4:$H$100)+SUMIF('AvsD_M6'!$B$4:$B$100,B4,'AvsD_M6'!$H$4:$H$100)+SUMIF('BvsC_M1'!$B$4:$B$100,B4,'BvsC_M1'!$H$4:$H$100)+SUMIF('BvsC_M2'!$B$4:$B$100,B4,'BvsC_M2'!$H$4:$H$100)+SUMIF('BvsC_M3'!$B$4:$B$100,B4,'BvsC_M3'!$H$4:$H$100)+SUMIF('BvsC_M4'!$B$4:$B$100,B4,'BvsC_M4'!$H$4:$H$100)+SUMIF('BvsC_M5'!$B$4:$B$100,B4,'BvsC_M5'!$H$4:$H$100)+SUMIF('BvsC_M6'!$B$4:$B$100,B4,'BvsC_M6'!$H$4:$H$100) | J4: =SUMIF('AvsB_M1'!$B$4:$B$100,B4,'AvsB_M1'!$I$4:$I$100)+SUMIF('AvsB_M2'!$B$4:$B$100,B4,'AvsB_M2'!$I$4:$I$100)+SUMIF('AvsB_M3'!$B$4:$B$100,B4,'AvsB_M3'!$I$4:$I$100)+SUMIF('AvsB_M4'!$B$4:$B$100,B4,'AvsB_M4'!$I$4:$I$100)+SUMIF('AvsB_M5'!$B$4:$B$100,B4,'AvsB_M5'!$I$4:$I$100)+SUMIF('AvsB_M6'!$B$4:$B$100,B4,'AvsB_M6'!$I$4:$I$100)+SUMIF('CvsD_M1'!$B$4:$B$100,B4,'CvsD_M1'!$I$4:$I$100)+SUMIF('CvsD_M2'!$B$4:$B$100,B4,'CvsD_M2'!$I$4:$I$100)+SUMIF('CvsD_M3'!$B$4:$B$100,B4,'CvsD_M3'!$I$4:$I$100)+SUMIF('CvsD_M4'!$B$4:$B$100,B4,'CvsD_M4'!$I$4:$I$100)+SUMIF('CvsD_M5'!$B$4:$B$100,B4,'CvsD_M5'!$I$4:$I$100)+SUMIF('CvsD_M6'!$B$4:$B$100,B4,'CvsD_M6'!$I$4:$I$100)+SUMIF('AvsC_M1'!$B$4:$B$100,B4,'AvsC_M1'!$I$4:$I$100)+SUMIF('AvsC_M2'!$B$4:$B$100,B4,'AvsC_M2'!$I$4:$I$100)+SUMIF('AvsC_M3'!$B$4:$B$100,B4,'AvsC_M3'!$I$4:$I$100)+SUMIF('AvsC_M4'!$B$4:$B$100,B4,'AvsC_M4'!$I$4:$I$100)+SUMIF('AvsC_M5'!$B$4:$B$100,B4,'AvsC_M5'!$I$4:$I$100)+SUMIF('AvsC_M6'!$B$4:$B$100,B4,'AvsC_M6'!$I$4:$I$100)+SUMIF('BvsD_M1'!$B$4:$B$100,B4,'BvsD_M1'!$I$4:$I$100)+SUMIF('BvsD_M2'!$B$4:$B$100,B4,'BvsD_M2'!$I$4:$I$100)+SUMIF('BvsD_M3'!$B$4:$B$100,B4,'BvsD_M3'!$I$4:$I$100)+SUMIF('BvsD_M4'!$B$4:$B$100,B4,'BvsD_M4'!$I$4:$I$100)+SUMIF('BvsD_M5'!$B$4:$B$100,B4,'BvsD_M5'!$I$4:$I$100)+SUMIF('BvsD_M6'!$B$4:$B$100,B4,'BvsD_M6'!$I$4:$I$100)+SUMIF('AvsD_M1'!$B$4:$B$100,B4,'AvsD_M1'!$I$4:$I$100)+SUMIF('AvsD_M2'!$B$4:$B$100,B4,'AvsD_M2'!$I$4:$I$100)+SUMIF('AvsD_M3'!$B$4:$B$100,B4,'AvsD_M3'!$I$4:$I$100)+SUMIF('AvsD_M4'!$B$4:$B$100,B4,'AvsD_M4'!$I$4:$I$100)+SUMIF('AvsD_M5'!$B$4:$B$100,B4,'AvsD_M5'!$I$4:$I$100)+SUMIF('AvsD_M6'!$B$4:$B$100,B4,'AvsD_M6'!$I$4:$I$100)+SUMIF('BvsC_M1'!$B$4:$B$100,B4,'BvsC_M1'!$I$4:$I$100)+SUMIF('BvsC_M2'!$B$4:$B$100,B4,'BvsC_M2'!$I$4:$I$100)+SUMIF('BvsC_M3'!$B$4:$B$100,B4,'BvsC_M3'!$I$4:$I$100)+SUMIF('BvsC_M4'!$B$4:$B$100,B4,'BvsC_M4'!$I$4:$I$100)+SUMIF('BvsC_M5'!$B$4:$B$100,B4,'BvsC_M5'!$I$4:$I$100)+SUMIF('BvsC_M6'!$B$4:$B$100,B4,'BvsC_M6'!$I$4:$I$100)
A5: 2 | B5: AIMLEGIT | C5: =COUNTIF('AvsB_M1'!$B$4:$B$100,B5)+COUNTIF('AvsB_M2'!$B$4:$B$100,B5)+COUNTIF('AvsB_M3'!$B$4:$B$100,B5)+COUNTIF('AvsB_M4'!$B$4:$B$100,B5)+COUNTIF('AvsB_M5'!$B$4:$B$100,B5)+COUNTIF('AvsB_M6'!$B$4:$B$100,B5)+COUNTIF('CvsD_M1'!$B$4:$B$100,B5)+COUNTIF('CvsD_M2'!$B$4:$B$100,B5)+COUNTIF('CvsD_M3'!$B$4:$B$100,B5)+COUNTIF('CvsD_M4'!$B$4:$B$100,B5)+COUNTIF('CvsD_M5'!$B$4:$B$100,B5)+COUNTIF('CvsD_M6'!$B$4:$B$100,B5)+COUNTIF('AvsC_M1'!$B$4:$B$100,B5)+COUNTIF('AvsC_M2'!$B$4:$B$100,B5)+COUNTIF('AvsC_M3'!$B$4:$B$100,B5)+COUNTIF('AvsC_M4'!$B$4:$B$100,B5)+COUNTIF('AvsC_M5'!$B$4:$B$100,B5)+COUNTIF('AvsC_M6'!$B$4:$B$100,B5)+COUNTIF('BvsD_M1'!$B$4:$B$100,B5)+COUNTIF('BvsD_M2'!$B$4:$B$100,B5)+COUNTIF('BvsD_M3'!$B$4:$B$100,B5)+COUNTIF('BvsD_M4'!$B$4:$B$100,B5)+COUNTIF('BvsD_M5'!$B$4:$B$100,B5)+COUNTIF('BvsD_M6'!$B$4:$B$100,B5)+COUNTIF('AvsD_M1'!$B$4:$B$100,B5)+COUNTIF('AvsD_M2'!$B$4:$B$100,B5)+COUNTIF('AvsD_M3'!$B$4:$B$100,B5)+COUNTIF('AvsD_M4'!$B$4:$B$100,B5)+COUNTIF('AvsD_M5'!$B$4:$B$100,B5)+COUNTIF('AvsD_M6'!$B$4:$B$100,B5)+COUNTIF('BvsC_M1'!$B$4:$B$100,B5)+COUNTIF('BvsC_M2'!$B$4:$B$100,B5)+COUNTIF('BvsC_M3'!$B$4:$B$100,B5)+COUNTIF('BvsC_M4'!$B$4:$B$100,B5)+COUNTIF('BvsC_M5'!$B$4:$B$100,B5)+COUNTIF('BvsC_M6'!$B$4:$B$100,B5) | D5: =SUMIF('AvsB_M1'!$B$4:$B$100,B5,'AvsB_M1'!$C$4:$C$100)+SUMIF('AvsB_M2'!$B$4:$B$100,B5,'AvsB_M2'!$C$4:$C$100)+SUMIF('AvsB_M3'!$B$4:$B$100,B5,'AvsB_M3'!$C$4:$C$100)+SUMIF('AvsB_M4'!$B$4:$B$100,B5,'AvsB_M4'!$C$4:$C$100)+SUMIF('AvsB_M5'!$B$4:$B$100,B5,'AvsB_M5'!$C$4:$C$100)+SUMIF('AvsB_M6'!$B$4:$B$100,B5,'AvsB_M6'!$C$4:$C$100)+SUMIF('CvsD_M1'!$B$4:$B$100,B5,'CvsD_M1'!$C$4:$C$100)+SUMIF('CvsD_M2'!$B$4:$B$100,B5,'CvsD_M2'!$C$4:$C$100)+SUMIF('CvsD_M3'!$B$4:$B$100,B5,'CvsD_M3'!$C$4:$C$100)+SUMIF('CvsD_M4'!$B$4:$B$100,B5,'CvsD_M4'!$C$4:$C$100)+SUMIF('CvsD_M5'!$B$4:$B$100,B5,'CvsD_M5'!$C$4:$C$100)+SUMIF('CvsD_M6'!$B$4:$B$100,B5,'CvsD_M6'!$C$4:$C$100)+SUMIF('AvsC_M1'!$B$4:$B$100,B5,'AvsC_M1'!$C$4:$C$100)+SUMIF('AvsC_M2'!$B$4:$B$100,B5,'AvsC_M2'!$C$4:$C$100)+SUMIF('AvsC_M3'!$B$4:$B$100,B5,'AvsC_M3'!$C$4:$C$100)+SUMIF('AvsC_M4'!$B$4:$B$100,B5,'AvsC_M4'!$C$4:$C$100)+SUMIF('AvsC_M5'!$B$4:$B$100,B5,'AvsC_M5'!$C$4:$C$100)+SUMIF('AvsC_M6'!$B$4:$B$100,B5,'AvsC_M6'!$C$4:$C$100)+SUMIF('BvsD_M1'!$B$4:$B$100,B5,'BvsD_M1'!$C$4:$C$100)+SUMIF('BvsD_M2'!$B$4:$B$100,B5,'BvsD_M2'!$C$4:$C$100)+SUMIF('BvsD_M3'!$B$4:$B$100,B5,'BvsD_M3'!$C$4:$C$100)+SUMIF('BvsD_M4'!$B$4:$B$100,B5,'BvsD_M4'!$C$4:$C$100)+SUMIF('BvsD_M5'!$B$4:$B$100,B5,'BvsD_M5'!$C$4:$C$100)+SUMIF('BvsD_M6'!$B$4:$B$100,B5,'BvsD_M6'!$C$4:$C$100)+SUMIF('AvsD_M1'!$B$4:$B$100,B5,'AvsD_M1'!$C$4:$C$100)+SUMIF('AvsD_M2'!$B$4:$B$100,B5,'AvsD_M2'!$C$4:$C$100)+SUMIF('AvsD_M3'!$B$4:$B$100,B5,'AvsD_M3'!$C$4:$C$100)+SUMIF('AvsD_M4'!$B$4:$B$100,B5,'AvsD_M4'!$C$4:$C$100)+SUMIF('AvsD_M5'!$B$4:$B$100,B5,'AvsD_M5'!$C$4:$C$100)+SUMIF('AvsD_M6'!$B$4:$B$100,B5,'AvsD_M6'!$C$4:$C$100)+SUMIF('BvsC_M1'!$B$4:$B$100,B5,'BvsC_M1'!$C$4:$C$100)+SUMIF('BvsC_M2'!$B$4:$B$100,B5,'BvsC_M2'!$C$4:$C$100)+SUMIF('BvsC_M3'!$B$4:$B$100,B5,'BvsC_M3'!$C$4:$C$100)+SUMIF('BvsC_M4'!$B$4:$B$100,B5,'BvsC_M4'!$C$4:$C$100)+SUMIF('BvsC_M5'!$B$4:$B$100,B5,'BvsC_M5'!$C$4:$C$100)+SUMIF('BvsC_M6'!$B$4:$B$100,B5,'BvsC_M6'!$C$4:$C$100) | E5: =SUMIF('AvsB_M1'!$B$4:$B$100,B5,'AvsB_M1'!$D$4:$D$100)+SUMIF('AvsB_M2'!$B$4:$B$100,B5,'AvsB_M2'!$D$4:$D$100)+SUMIF('AvsB_M3'!$B$4:$B$100,B5,'AvsB_M3'!$D$4:$D$100)+SUMIF('AvsB_M4'!$B$4:$B$100,B5,'AvsB_M4'!$D$4:$D$100)+SUMIF('AvsB_M5'!$B$4:$B$100,B5,'AvsB_M5'!$D$4:$D$100)+SUMIF('AvsB_M6'!$B$4:$B$100,B5,'AvsB_M6'!$D$4:$D$100)+SUMIF('CvsD_M1'!$B$4:$B$100,B5,'CvsD_M1'!$D$4:$D$100)+SUMIF('CvsD_M2'!$B$4:$B$100,B5,'CvsD_M2'!$D$4:$D$100)+SUMIF('CvsD_M3'!$B$4:$B$100,B5,'CvsD_M3'!$D$4:$D$100)+SUMIF('CvsD_M4'!$B$4:$B$100,B5,'CvsD_M4'!$D$4:$D$100)+SUMIF('CvsD_M5'!$B$4:$B$100,B5,'CvsD_M5'!$D$4:$D$100)+SUMIF('CvsD_M6'!$B$4:$B$100,B5,'CvsD_M6'!$D$4:$D$100)+SUMIF('AvsC_M1'!$B$4:$B$100,B5,'AvsC_M1'!$D$4:$D$100)+SUMIF('AvsC_M2'!$B$4:$B$100,B5,'AvsC_M2'!$D$4:$D$100)+SUMIF('AvsC_M3'!$B$4:$B$100,B5,'AvsC_M3'!$D$4:$D$100)+SUMIF('AvsC_M4'!$B$4:$B$100,B5,'AvsC_M4'!$D$4:$D$100)+SUMIF('AvsC_M5'!$B$4:$B$100,B5,'AvsC_M5'!$D$4:$D$100)+SUMIF('AvsC_M6'!$B$4:$B$100,B5,'AvsC_M6'!$D$4:$D$100)+SUMIF('BvsD_M1'!$B$4:$B$100,B5,'BvsD_M1'!$D$4:$D$100)+SUMIF('BvsD_M2'!$B$4:$B$100,B5,'BvsD_M2'!$D$4:$D$100)+SUMIF('BvsD_M3'!$B$4:$B$100,B5,'BvsD_M3'!$D$4:$D$100)+SUMIF('BvsD_M4'!$B$4:$B$100,B5,'BvsD_M4'!$D$4:$D$100)+SUMIF('BvsD_M5'!$B$4:$B$100,B5,'BvsD_M5'!$D$4:$D$100)+SUMIF('BvsD_M6'!$B$4:$B$100,B5,'BvsD_M6'!$D$4:$D$100)+SUMIF('AvsD_M1'!$B$4:$B$100,B5,'AvsD_M1'!$D$4:$D$100)+SUMIF('AvsD_M2'!$B$4:$B$100,B5,'AvsD_M2'!$D$4:$D$100)+SUMIF('AvsD_M3'!$B$4:$B$100,B5,'AvsD_M3'!$D$4:$D$100)+SUMIF('AvsD_M4'!$B$4:$B$100,B5,'AvsD_M4'!$D$4:$D$100)+SUMIF('AvsD_M5'!$B$4:$B$100,B5,'AvsD_M5'!$D$4:$D$100)+SUMIF('AvsD_M6'!$B$4:$B$100,B5,'AvsD_M6'!$D$4:$D$100)+SUMIF('BvsC_M1'!$B$4:$B$100,B5,'BvsC_M1'!$D$4:$D$100)+SUMIF('BvsC_M2'!$B$4:$B$100,B5,'BvsC_M2'!$D$4:$D$100)+SUMIF('BvsC_M3'!$B$4:$B$100,B5,'BvsC_M3'!$D$4:$D$100)+SUMIF('BvsC_M4'!$B$4:$B$100,B5,'BvsC_M4'!$D$4:$D$100)+SUMIF('BvsC_M5'!$B$4:$B$100,B5,'BvsC_M5'!$D$4:$D$100)+SUMIF('BvsC_M6'!$B$4:$B$100,B5,'BvsC_M6'!$D$4:$D$100) | F5: =SUMIF('AvsB_M1'!$B$4:$B$100,B5,'AvsB_M1'!$E$4:$E$100)+SUMIF('AvsB_M2'!$B$4:$B$100,B5,'AvsB_M2'!$E$4:$E$100)+SUMIF('AvsB_M3'!$B$4:$B$100,B5,'AvsB_M3'!$E$4:$E$100)+SUMIF('AvsB_M4'!$B$4:$B$100,B5,'AvsB_M4'!$E$4:$E$100)+SUMIF('AvsB_M5'!$B$4:$B$100,B5,'AvsB_M5'!$E$4:$E$100)+SUMIF('AvsB_M6'!$B$4:$B$100,B5,'AvsB_M6'!$E$4:$E$100)+SUMIF('CvsD_M1'!$B$4:$B$100,B5,'CvsD_M1'!$E$4:$E$100)+SUMIF('CvsD_M2'!$B$4:$B$100,B5,'CvsD_M2'!$E$4:$E$100)+SUMIF('CvsD_M3'!$B$4:$B$100,B5,'CvsD_M3'!$E$4:$E$100)+SUMIF('CvsD_M4'!$B$4:$B$100,B5,'CvsD_M4'!$E$4:$E$100)+SUMIF('CvsD_M5'!$B$4:$B$100,B5,'CvsD_M5'!$E$4:$E$100)+SUMIF('CvsD_M6'!$B$4:$B$100,B5,'CvsD_M6'!$E$4:$E$100)+SUMIF('AvsC_M1'!$B$4:$B$100,B5,'AvsC_M1'!$E$4:$E$100)+SUMIF('AvsC_M2'!$B$4:$B$100,B5,'AvsC_M2'!$E$4:$E$100)+SUMIF('AvsC_M3'!$B$4:$B$100,B5,'AvsC_M3'!$E$4:$E$100)+SUMIF('AvsC_M4'!$B$4:$B$100,B5,'AvsC_M4'!$E$4:$E$100)+SUMIF('AvsC_M5'!$B$4:$B$100,B5,'AvsC_M5'!$E$4:$E$100)+SUMIF('AvsC_M6'!$B$4:$B$100,B5,'AvsC_M6'!$E$4:$E$100)+SUMIF('BvsD_M1'!$B$4:$B$100,B5,'BvsD_M1'!$E$4:$E$100)+SUMIF('BvsD_M2'!$B$4:$B$100,B5,'BvsD_M2'!$E$4:$E$100)+SUMIF('BvsD_M3'!$B$4:$B$100,B5,'BvsD_M3'!$E$4:$E$100)+SUMIF('BvsD_M4'!$B$4:$B$100,B5,'BvsD_M4'!$E$4:$E$100)+SUMIF('BvsD_M5'!$B$4:$B$100,B5,'BvsD_M5'!$E$4:$E$100)+SUMIF('BvsD_M6'!$B$4:$B$100,B5,'BvsD_M6'!$E$4:$E$100)+SUMIF('AvsD_M1'!$B$4:$B$100,B5,'AvsD_M1'!$E$4:$E$100)+SUMIF('AvsD_M2'!$B$4:$B$100,B5,'AvsD_M2'!$E$4:$E$100)+SUMIF('AvsD_M3'!$B$4:$B$100,B5,'AvsD_M3'!$E$4:$E$100)+SUMIF('AvsD_M4'!$B$4:$B$100,B5,'AvsD_M4'!$E$4:$E$100)+SUMIF('AvsD_M5'!$B$4:$B$100,B5,'AvsD_M5'!$E$4:$E$100)+SUMIF('AvsD_M6'!$B$4:$B$100,B5,'AvsD_M6'!$E$4:$E$100)+SUMIF('BvsC_M1'!$B$4:$B$100,B5,'BvsC_M1'!$E$4:$E$100)+SUMIF('BvsC_M2'!$B$4:$B$100,B5,'BvsC_M2'!$E$4:$E$100)+SUMIF('BvsC_M3'!$B$4:$B$100,B5,'BvsC_M3'!$E$4:$E$100)+SUMIF('BvsC_M4'!$B$4:$B$100,B5,'BvsC_M4'!$E$4:$E$100)+SUMIF('BvsC_M5'!$B$4:$B$100,B5,'BvsC_M5'!$E$4:$E$100)+SUMIF('BvsC_M6'!$B$4:$B$100,B5,'BvsC_M6'!$E$4:$E$100) | G5: =SUMIF('AvsB_M1'!$B$4:$B$100,B5,'AvsB_M1'!$F$4:$F$100)+SUMIF('AvsB_M2'!$B$4:$B$100,B5,'AvsB_M2'!$F$4:$F$100)+SUMIF('AvsB_M3'!$B$4:$B$100,B5,'AvsB_M3'!$F$4:$F$100)+SUMIF('AvsB_M4'!$B$4:$B$100,B5,'AvsB_M4'!$F$4:$F$100)+SUMIF('AvsB_M5'!$B$4:$B$100,B5,'AvsB_M5'!$F$4:$F$100)+SUMIF('AvsB_M6'!$B$4:$B$100,B5,'AvsB_M6'!$F$4:$F$100)+SUMIF('CvsD_M1'!$B$4:$B$100,B5,'CvsD_M1'!$F$4:$F$100)+SUMIF('CvsD_M2'!$B$4:$B$100,B5,'CvsD_M2'!$F$4:$F$100)+SUMIF('CvsD_M3'!$B$4:$B$100,B5,'CvsD_M3'!$F$4:$F$100)+SUMIF('CvsD_M4'!$B$4:$B$100,B5,'CvsD_M4'!$F$4:$F$100)+SUMIF('CvsD_M5'!$B$4:$B$100,B5,'CvsD_M5'!$F$4:$F$100)+SUMIF('CvsD_M6'!$B$4:$B$100,B5,'CvsD_M6'!$F$4:$F$100)+SUMIF('AvsC_M1'!$B$4:$B$100,B5,'AvsC_M1'!$F$4:$F$100)+SUMIF('AvsC_M2'!$B$4:$B$100,B5,'AvsC_M2'!$F$4:$F$100)+SUMIF('AvsC_M3'!$B$4:$B$100,B5,'AvsC_M3'!$F$4:$F$100)+SUMIF('AvsC_M4'!$B$4:$B$100,B5,'AvsC_M4'!$F$4:$F$100)+SUMIF('AvsC_M5'!$B$4:$B$100,B5,'AvsC_M5'!$F$4:$F$100)+SUMIF('AvsC_M6'!$B$4:$B$100,B5,'AvsC_M6'!$F$4:$F$100)+SUMIF('BvsD_M1'!$B$4:$B$100,B5,'BvsD_M1'!$F$4:$F$100)+SUMIF('BvsD_M2'!$B$4:$B$100,B5,'BvsD_M2'!$F$4:$F$100)+SUMIF('BvsD_M3'!$B$4:$B$100,B5,'BvsD_M3'!$F$4:$F$100)+SUMIF('BvsD_M4'!$B$4:$B$100,B5,'BvsD_M4'!$F$4:$F$100)+SUMIF('BvsD_M5'!$B$4:$B$100,B5,'BvsD_M5'!$F$4:$F$100)+SUMIF('BvsD_M6'!$B$4:$B$100,B5,'BvsD_M6'!$F$4:$F$100)+SUMIF('AvsD_M1'!$B$4:$B$100,B5,'AvsD_M1'!$F$4:$F$100)+SUMIF('AvsD_M2'!$B$4:$B$100,B5,'AvsD_M2'!$F$4:$F$100)+SUMIF('AvsD_M3'!$B$4:$B$100,B5,'AvsD_M3'!$F$4:$F$100)+SUMIF('AvsD_M4'!$B$4:$B$100,B5,'AvsD_M4'!$F$4:$F$100)+SUMIF('AvsD_M5'!$B$4:$B$100,B5,'AvsD_M5'!$F$4:$F$100)+SUMIF('AvsD_M6'!$B$4:$B$100,B5,'AvsD_M6'!$F$4:$F$100)+SUMIF('BvsC_M1'!$B$4:$B$100,B5,'BvsC_M1'!$F$4:$F$100)+SUMIF('BvsC_M2'!$B$4:$B$100,B5,'BvsC_M2'!$F$4:$F$100)+SUMIF('BvsC_M3'!$B$4:$B$100,B5,'BvsC_M3'!$F$4:$F$100)+SUMIF('BvsC_M4'!$B$4:$B$100,B5,'BvsC_M4'!$F$4:$F$100)+SUMIF('BvsC_M5'!$B$4:$B$100,B5,'BvsC_M5'!$F$4:$F$100)+SUMIF('BvsC_M6'!$B$4:$B$100,B5,'BvsC_M6'!$F$4:$F$100) | H5: =SUMIF('AvsB_M1'!$B$4:$B$100,B5,'AvsB_M1'!$G$4:$G$100)+SUMIF('AvsB_M2'!$B$4:$B$100,B5,'AvsB_M2'!$G$4:$G$100)+SUMIF('AvsB_M3'!$B$4:$B$100,B5,'AvsB_M3'!$G$4:$G$100)+SUMIF('AvsB_M4'!$B$4:$B$100,B5,'AvsB_M4'!$G$4:$G$100)+SUMIF('AvsB_M5'!$B$4:$B$100,B5,'AvsB_M5'!$G$4:$G$100)+SUMIF('AvsB_M6'!$B$4:$B$100,B5,'AvsB_M6'!$G$4:$G$100)+SUMIF('CvsD_M1'!$B$4:$B$100,B5,'CvsD_M1'!$G$4:$G$100)+SUMIF('CvsD_M2'!$B$4:$B$100,B5,'CvsD_M2'!$G$4:$G$100)+SUMIF('CvsD_M3'!$B$4:$B$100,B5,'CvsD_M3'!$G$4:$G$100)+SUMIF('CvsD_M4'!$B$4:$B$100,B5,'CvsD_M4'!$G$4:$G$100)+SUMIF('CvsD_M5'!$B$4:$B$100,B5,'CvsD_M5'!$G$4:$G$100)+SUMIF('CvsD_M6'!$B$4:$B$100,B5,'CvsD_M6'!$G$4:$G$100)+SUMIF('AvsC_M1'!$B$4:$B$100,B5,'AvsC_M1'!$G$4:$G$100)+SUMIF('AvsC_M2'!$B$4:$B$100,B5,'AvsC_M2'!$G$4:$G$100)+SUMIF('AvsC_M3'!$B$4:$B$100,B5,'AvsC_M3'!$G$4:$G$100)+SUMIF('AvsC_M4'!$B$4:$B$100,B5,'AvsC_M4'!$G$4:$G$100)+SUMIF('AvsC_M5'!$B$4:$B$100,B5,'AvsC_M5'!$G$4:$G$100)+SUMIF('AvsC_M6'!$B$4:$B$100,B5,'AvsC_M6'!$G$4:$G$100)+SUMIF('BvsD_M1'!$B$4:$B$100,B5,'BvsD_M1'!$G$4:$G$100)+SUMIF('BvsD_M2'!$B$4:$B$100,B5,'BvsD_M2'!$G$4:$G$100)+SUMIF('BvsD_M3'!$B$4:$B$100,B5,'BvsD_M3'!$G$4:$G$100)+SUMIF('BvsD_M4'!$B$4:$B$100,B5,'BvsD_M4'!$G$4:$G$100)+SUMIF('BvsD_M5'!$B$4:$B$100,B5,'BvsD_M5'!$G$4:$G$100)+SUMIF('BvsD_M6'!$B$4:$B$100,B5,'BvsD_M6'!$G$4:$G$100)+SUMIF('AvsD_M1'!$B$4:$B$100,B5,'AvsD_M1'!$G$4:$G$100)+SUMIF('AvsD_M2'!$B$4:$B$100,B5,'AvsD_M2'!$G$4:$G$100)+SUMIF('AvsD_M3'!$B$4:$B$100,B5,'AvsD_M3'!$G$4:$G$100)+SUMIF('AvsD_M4'!$B$4:$B$100,B5,'AvsD_M4'!$G$4:$G$100)+SUMIF('AvsD_M5'!$B$4:$B$100,B5,'AvsD_M5'!$G$4:$G$100)+SUMIF('AvsD_M6'!$B$4:$B$100,B5,'AvsD_M6'!$G$4:$G$100)+SUMIF('BvsC_M1'!$B$4:$B$100,B5,'BvsC_M1'!$G$4:$G$100)+SUMIF('BvsC_M2'!$B$4:$B$100,B5,'BvsC_M2'!$G$4:$G$100)+SUMIF('BvsC_M3'!$B$4:$B$100,B5,'BvsC_M3'!$G$4:$G$100)+SUMIF('BvsC_M4'!$B$4:$B$100,B5,'BvsC_M4'!$G$4:$G$100)+SUMIF('BvsC_M5'!$B$4:$B$100,B5,'BvsC_M5'!$G$4:$G$100)+SUMIF('BvsC_M6'!$B$4:$B$100,B5,'BvsC_M6'!$G$4:$G$100) | I5: =SUMIF('AvsB_M1'!$B$4:$B$100,B5,'AvsB_M1'!$H$4:$H$100)+SUMIF('AvsB_M2'!$B$4:$B$100,B5,'AvsB_M2'!$H$4:$H$100)+SUMIF('AvsB_M3'!$B$4:$B$100,B5,'AvsB_M3'!$H$4:$H$100)+SUMIF('AvsB_M4'!$B$4:$B$100,B5,'AvsB_M4'!$H$4:$H$100)+SUMIF('AvsB_M5'!$B$4:$B$100,B5,'AvsB_M5'!$H$4:$H$100)+SUMIF('AvsB_M6'!$B$4:$B$100,B5,'AvsB_M6'!$H$4:$H$100)+SUMIF('CvsD_M1'!$B$4:$B$100,B5,'CvsD_M1'!$H$4:$H$100)+SUMIF('CvsD_M2'!$B$4:$B$100,B5,'CvsD_M2'!$H$4:$H$100)+SUMIF('CvsD_M3'!$B$4:$B$100,B5,'CvsD_M3'!$H$4:$H$100)+SUMIF('CvsD_M4'!$B$4:$B$100,B5,'CvsD_M4'!$H$4:$H$100)+SUMIF('CvsD_M5'!$B$4:$B$100,B5,'CvsD_M5'!$H$4:$H$100)+SUMIF('CvsD_M6'!$B$4:$B$100,B5,'CvsD_M6'!$H$4:$H$100)+SUMIF('AvsC_M1'!$B$4:$B$100,B5,'AvsC_M1'!$H$4:$H$100)+SUMIF('AvsC_M2'!$B$4:$B$100,B5,'AvsC_M2'!$H$4:$H$100)+SUMIF('AvsC_M3'!$B$4:$B$100,B5,'AvsC_M3'!$H$4:$H$100)+SUMIF('AvsC_M4'!$B$4:$B$100,B5,'AvsC_M4'!$H$4:$H$100)+SUMIF('AvsC_M5'!$B$4:$B$100,B5,'AvsC_M5'!$H$4:$H$100)+SUMIF('AvsC_M6'!$B$4:$B$100,B5,'AvsC_M6'!$H$4:$H$100)+SUMIF('BvsD_M1'!$B$4:$B$100,B5,'BvsD_M1'!$H$4:$H$100)+SUMIF('BvsD_M2'!$B$4:$B$100,B5,'BvsD_M2'!$H$4:$H$100)+SUMIF('BvsD_M3'!$B$4:$B$100,B5,'BvsD_M3'!$H$4:$H$100)+SUMIF('BvsD_M4'!$B$4:$B$100,B5,'BvsD_M4'!$H$4:$H$100)+SUMIF('BvsD_M5'!$B$4:$B$100,B5,'BvsD_M5'!$H$4:$H$100)+SUMIF('BvsD_M6'!$B$4:$B$100,B5,'BvsD_M6'!$H$4:$H$100)+SUMIF('AvsD_M1'!$B$4:$B$100,B5,'AvsD_M1'!$H$4:$H$100)+SUMIF('AvsD_M2'!$B$4:$B$100,B5,'AvsD_M2'!$H$4:$H$100)+SUMIF('AvsD_M3'!$B$4:$B$100,B5,'AvsD_M3'!$H$4:$H$100)+SUMIF('AvsD_M4'!$B$4:$B$100,B5,'AvsD_M4'!$H$4:$H$100)+SUMIF('AvsD_M5'!$B$4:$B$100,B5,'AvsD_M5'!$H$4:$H$100)+SUMIF('AvsD_M6'!$B$4:$B$100,B5,'AvsD_M6'!$H$4:$H$100)+SUMIF('BvsC_M1'!$B$4:$B$100,B5,'BvsC_M1'!$H$4:$H$100)+SUMIF('BvsC_M2'!$B$4:$B$100,B5,'BvsC_M2'!$H$4:$H$100)+SUMIF('BvsC_M3'!$B$4:$B$100,B5,'BvsC_M3'!$H$4:$H$100)+SUMIF('BvsC_M4'!$B$4:$B$100,B5,'BvsC_M4'!$H$4:$H$100)+SUMIF('BvsC_M5'!$B$4:$B$100,B5,'BvsC_M5'!$H$4:$H$100)+SUMIF('BvsC_M6'!$B$4:$B$100,B5,'BvsC_M6'!$H$4:$H$100) | J5: =SUMIF('AvsB_M1'!$B$4:$B$100,B5,'AvsB_M1'!$I$4:$I$100)+SUMIF('AvsB_M2'!$B$4:$B$100,B5,'AvsB_M2'!$I$4:$I$100)+SUMIF('AvsB_M3'!$B$4:$B$100,B5,'AvsB_M3'!$I$4:$I$100)+SUMIF('AvsB_M4'!$B$4:$B$100,B5,'AvsB_M4'!$I$4:$I$100)+SUMIF('AvsB_M5'!$B$4:$B$100,B5,'AvsB_M5'!$I$4:$I$100)+SUMIF('AvsB_M6'!$B$4:$B$100,B5,'AvsB_M6'!$I$4:$I$100)+SUMIF('CvsD_M1'!$B$4:$B$100,B5,'CvsD_M1'!$I$4:$I$100)+SUMIF('CvsD_M2'!$B$4:$B$100,B5,'CvsD_M2'!$I$4:$I$100)+SUMIF('CvsD_M3'!$B$4:$B$100,B5,'CvsD_M3'!$I$4:$I$100)+SUMIF('CvsD_M4'!$B$4:$B$100,B5,'CvsD_M4'!$I$4:$I$100)+SUMIF('CvsD_M5'!$B$4:$B$100,B5,'CvsD_M5'!$I$4:$I$100)+SUMIF('CvsD_M6'!$B$4:$B$100,B5,'CvsD_M6'!$I$4:$I$100)+SUMIF('AvsC_M1'!$B$4:$B$100,B5,'AvsC_M1'!$I$4:$I$100)+SUMIF('AvsC_M2'!$B$4:$B$100,B5,'AvsC_M2'!$I$4:$I$100)+SUMIF('AvsC_M3'!$B$4:$B$100,B5,'AvsC_M3'!$I$4:$I$100)+SUMIF('AvsC_M4'!$B$4:$B$100,B5,'AvsC_M4'!$I$4:$I$100)+SUMIF('AvsC_M5'!$B$4:$B$100,B5,'AvsC_M5'!$I$4:$I$100)+SUMIF('AvsC_M6'!$B$4:$B$100,B5,'AvsC_M6'!$I$4:$I$100)+SUMIF('BvsD_M1'!$B$4:$B$100,B5,'BvsD_M1'!$I$4:$I$100)+SUMIF('BvsD_M2'!$B$4:$B$100,B5,'BvsD_M2'!$I$4:$I$100)+SUMIF('BvsD_M3'!$B$4:$B$100,B5,'BvsD_M3'!$I$4:$I$100)+SUMIF('BvsD_M4'!$B$4:$B$100,B5,'BvsD_M4'!$I$4:$I$100)+SUMIF('BvsD_M5'!$B$4:$B$100,B5,'BvsD_M5'!$I$4:$I$100)+SUMIF('BvsD_M6'!$B$4:$B$100,B5,'BvsD_M6'!$I$4:$I$100)+SUMIF('AvsD_M1'!$B$4:$B$100,B5,'AvsD_M1'!$I$4:$I$100)+SUMIF('AvsD_M2'!$B$4:$B$100,B5,'AvsD_M2'!$I$4:$I$100)+SUMIF('AvsD_M3'!$B$4:$B$100,B5,'AvsD_M3'!$I$4:$I$100)+SUMIF('AvsD_M4'!$B$4:$B$100,B5,'AvsD_M4'!$I$4:$I$100)+SUMIF('AvsD_M5'!$B$4:$B$100,B5,'AvsD_M5'!$I$4:$I$100)+SUMIF('AvsD_M6'!$B$4:$B$100,B5,'AvsD_M6'!$I$4:$I$100)+SUMIF('BvsC_M1'!$B$4:$B$100,B5,'BvsC_M1'!$I$4:$I$100)+SUMIF('BvsC_M2'!$B$4:$B$100,B5,'BvsC_M2'!$I$4:$I$100)+SUMIF('BvsC_M3'!$B$4:$B$100,B5,'BvsC_M3'!$I$4:$I$100)+SUMIF('BvsC_M4'!$B$4:$B$100,B5,'BvsC_M4'!$I$4:$I$100)+SUMIF('BvsC_M5'!$B$4:$B$100,B5,'BvsC_M5'!$I$4:$I$100)+SUMIF('BvsC_M6'!$B$4:$B$100,B5,'BvsC_M6'!$I$4:$I$100)
A6: 3 | B6: CITY TIGERS X | C6: =COUNTIF('AvsB_M1'!$B$4:$B$100,B6)+COUNTIF('AvsB_M2'!$B$4:$B$100,B6)+COUNTIF('AvsB_M3'!$B$4:$B$100,B6)+COUNTIF('AvsB_M4'!$B$4:$B$100,B6)+COUNTIF('AvsB_M5'!$B$4:$B$100,B6)+COUNTIF('AvsB_M6'!$B$4:$B$100,B6)+COUNTIF('CvsD_M1'!$B$4:$B$100,B6)+COUNTIF('CvsD_M2'!$B$4:$B$100,B6)+COUNTIF('CvsD_M3'!$B$4:$B$100,B6)+COUNTIF('CvsD_M4'!$B$4:$B$100,B6)+COUNTIF('CvsD_M5'!$B$4:$B$100,B6)+COUNTIF('CvsD_M6'!$B$4:$B$100,B6)+COUNTIF('AvsC_M1'!$B$4:$B$100,B6)+COUNTIF('AvsC_M2'!$B$4:$B$100,B6)+COUNTIF('AvsC_M3'!$B$4:$B$100,B6)+COUNTIF('AvsC_M4'!$B$4:$B$100,B6)+COUNTIF('AvsC_M5'!$B$4:$B$100,B6)+COUNTIF('AvsC_M6'!$B$4:$B$100,B6)+COUNTIF('BvsD_M1'!$B$4:$B$100,B6)+COUNTIF('BvsD_M2'!$B$4:$B$100,B6)+COUNTIF('BvsD_M3'!$B$4:$B$100,B6)+COUNTIF('BvsD_M4'!$B$4:$B$100,B6)+COUNTIF('BvsD_M5'!$B$4:$B$100,B6)+COUNTIF('BvsD_M6'!$B$4:$B$100,B6)+COUNTIF('AvsD_M1'!$B$4:$B$100,B6)+COUNTIF('AvsD_M2'!$B$4:$B$100,B6)+COUNTIF('AvsD_M3'!$B$4:$B$100,B6)+COUNTIF('AvsD_M4'!$B$4:$B$100,B6)+COUNTIF('AvsD_M5'!$B$4:$B$100,B6)+COUNTIF('AvsD_M6'!$B$4:$B$100,B6)+COUNTIF('BvsC_M1'!$B$4:$B$100,B6)+COUNTIF('BvsC_M2'!$B$4:$B$100,B6)+COUNTIF('BvsC_M3'!$B$4:$B$100,B6)+COUNTIF('BvsC_M4'!$B$4:$B$100,B6)+COUNTIF('BvsC_M5'!$B$4:$B$100,B6)+COUNTIF('BvsC_M6'!$B$4:$B$100,B6) | D6: =SUMIF('AvsB_M1'!$B$4:$B$100,B6,'AvsB_M1'!$C$4:$C$100)+SUMIF('AvsB_M2'!$B$4:$B$100,B6,'AvsB_M2'!$C$4:$C$100)+SUMIF('AvsB_M3'!$B$4:$B$100,B6,'AvsB_M3'!$C$4:$C$100)+SUMIF('AvsB_M4'!$B$4:$B$100,B6,'AvsB_M4'!$C$4:$C$100)+SUMIF('AvsB_M5'!$B$4:$B$100,B6,'AvsB_M5'!$C$4:$C$100)+SUMIF('AvsB_M6'!$B$4:$B$100,B6,'AvsB_M6'!$C$4:$C$100)+SUMIF('CvsD_M1'!$B$4:$B$100,B6,'CvsD_M1'!$C$4:$C$100)+SUMIF('CvsD_M2'!$B$4:$B$100,B6,'CvsD_M2'!$C$4:$C$100)+SUMIF('CvsD_M3'!$B$4:$B$100,B6,'CvsD_M3'!$C$4:$C$100)+SUMIF('CvsD_M4'!$B$4:$B$100,B6,'CvsD_M4'!$C$4:$C$100)+SUMIF('CvsD_M5'!$B$4:$B$100,B6,'CvsD_M5'!$C$4:$C$100)+SUMIF('CvsD_M6'!$B$4:$B$100,B6,'CvsD_M6'!$C$4:$C$100)+SUMIF('AvsC_M1'!$B$4:$B$100,B6,'AvsC_M1'!$C$4:$C$100)+SUMIF('AvsC_M2'!$B$4:$B$100,B6,'AvsC_M2'!$C$4:$C$100)+SUMIF('AvsC_M3'!$B$4:$B$100,B6,'AvsC_M3'!$C$4:$C$100)+SUMIF('AvsC_M4'!$B$4:$B$100,B6,'AvsC_M4'!$C$4:$C$100)+SUMIF('AvsC_M5'!$B$4:$B$100,B6,'AvsC_M5'!$C$4:$C$100)+SUMIF('AvsC_M6'!$B$4:$B$100,B6,'AvsC_M6'!$C$4:$C$100)+SUMIF('BvsD_M1'!$B$4:$B$100,B6,'BvsD_M1'!$C$4:$C$100)+SUMIF('BvsD_M2'!$B$4:$B$100,B6,'BvsD_M2'!$C$4:$C$100)+SUMIF('BvsD_M3'!$B$4:$B$100,B6,'BvsD_M3'!$C$4:$C$100)+SUMIF('BvsD_M4'!$B$4:$B$100,B6,'BvsD_M4'!$C$4:$C$100)+SUMIF('BvsD_M5'!$B$4:$B$100,B6,'BvsD_M5'!$C$4:$C$100)+SUMIF('BvsD_M6'!$B$4:$B$100,B6,'BvsD_M6'!$C$4:$C$100)+SUMIF('AvsD_M1'!$B$4:$B$100,B6,'AvsD_M1'!$C$4:$C$100)+SUMIF('AvsD_M2'!$B$4:$B$100,B6,'AvsD_M2'!$C$4:$C$100)+SUMIF('AvsD_M3'!$B$4:$B$100,B6,'AvsD_M3'!$C$4:$C$100)+SUMIF('AvsD_M4'!$B$4:$B$100,B6,'AvsD_M4'!$C$4:$C$100)+SUMIF('AvsD_M5'!$B$4:$B$100,B6,'AvsD_M5'!$C$4:$C$100)+SUMIF('AvsD_M6'!$B$4:$B$100,B6,'AvsD_M6'!$C$4:$C$100)+SUMIF('BvsC_M1'!$B$4:$B$100,B6,'BvsC_M1'!$C$4:$C$100)+SUMIF('BvsC_M2'!$B$4:$B$100,B6,'BvsC_M2'!$C$4:$C$100)+SUMIF('BvsC_M3'!$B$4:$B$100,B6,'BvsC_M3'!$C$4:$C$100)+SUMIF('BvsC_M4'!$B$4:$B$100,B6,'BvsC_M4'!$C$4:$C$100)+SUMIF('BvsC_M5'!$B$4:$B$100,B6,'BvsC_M5'!$C$4:$C$100)+SUMIF('BvsC_M6'!$B$4:$B$100,B6,'BvsC_M6'!$C$4:$C$100) | E6: =SUMIF('AvsB_M1'!$B$4:$B$100,B6,'AvsB_M1'!$D$4:$D$100)+SUMIF('AvsB_M2'!$B$4:$B$100,B6,'AvsB_M2'!$D$4:$D$100)+SUMIF('AvsB_M3'!$B$4:$B$100,B6,'AvsB_M3'!$D$4:$D$100)+SUMIF('AvsB_M4'!$B$4:$B$100,B6,'AvsB_M4'!$D$4:$D$100)+SUMIF('AvsB_M5'!$B$4:$B$100,B6,'AvsB_M5'!$D$4:$D$100)+SUMIF('AvsB_M6'!$B$4:$B$100,B6,'AvsB_M6'!$D$4:$D$100)+SUMIF('CvsD_M1'!$B$4:$B$100,B6,'CvsD_M1'!$D$4:$D$100)+SUMIF('CvsD_M2'!$B$4:$B$100,B6,'CvsD_M2'!$D$4:$D$100)+SUMIF('CvsD_M3'!$B$4:$B$100,B6,'CvsD_M3'!$D$4:$D$100)+SUMIF('CvsD_M4'!$B$4:$B$100,B6,'CvsD_M4'!$D$4:$D$100)+SUMIF('CvsD_M5'!$B$4:$B$100,B6,'CvsD_M5'!$D$4:$D$100)+SUMIF('CvsD_M6'!$B$4:$B$100,B6,'CvsD_M6'!$D$4:$D$100)+SUMIF('AvsC_M1'!$B$4:$B$100,B6,'AvsC_M1'!$D$4:$D$100)+SUMIF('AvsC_M2'!$B$4:$B$100,B6,'AvsC_M2'!$D$4:$D$100)+SUMIF('AvsC_M3'!$B$4:$B$100,B6,'AvsC_M3'!$D$4:$D$100)+SUMIF('AvsC_M4'!$B$4:$B$100,B6,'AvsC_M4'!$D$4:$D$100)+SUMIF('AvsC_M5'!$B$4:$B$100,B6,'AvsC_M5'!$D$4:$D$100)+SUMIF('AvsC_M6'!$B$4:$B$100,B6,'AvsC_M6'!$D$4:$D$100)+SUMIF('BvsD_M1'!$B$4:$B$100,B6,'BvsD_M1'!$D$4:$D$100)+SUMIF('BvsD_M2'!$B$4:$B$100,B6,'BvsD_M2'!$D$4:$D$100)+SUMIF('BvsD_M3'!$B$4:$B$100,B6,'BvsD_M3'!$D$4:$D$100)+SUMIF('BvsD_M4'!$B$4:$B$100,B6,'BvsD_M4'!$D$4:$D$100)+SUMIF('BvsD_M5'!$B$4:$B$100,B6,'BvsD_M5'!$D$4:$D$100)+SUMIF('BvsD_M6'!$B$4:$B$100,B6,'BvsD_M6'!$D$4:$D$100)+SUMIF('AvsD_M1'!$B$4:$B$100,B6,'AvsD_M1'!$D$4:$D$100)+SUMIF('AvsD_M2'!$B$4:$B$100,B6,'AvsD_M2'!$D$4:$D$100)+SUMIF('AvsD_M3'!$B$4:$B$100,B6,'AvsD_M3'!$D$4:$D$100)+SUMIF('AvsD_M4'!$B$4:$B$100,B6,'AvsD_M4'!$D$4:$D$100)+SUMIF('AvsD_M5'!$B$4:$B$100,B6,'AvsD_M5'!$D$4:$D$100)+SUMIF('AvsD_M6'!$B$4:$B$100,B6,'AvsD_M6'!$D$4:$D$100)+SUMIF('BvsC_M1'!$B$4:$B$100,B6,'BvsC_M1'!$D$4:$D$100)+SUMIF('BvsC_M2'!$B$4:$B$100,B6,'BvsC_M2'!$D$4:$D$100)+SUMIF('BvsC_M3'!$B$4:$B$100,B6,'BvsC_M3'!$D$4:$D$100)+SUMIF('BvsC_M4'!$B$4:$B$100,B6,'BvsC_M4'!$D$4:$D$100)+SUMIF('BvsC_M5'!$B$4:$B$100,B6,'BvsC_M5'!$D$4:$D$100)+SUMIF('BvsC_M6'!$B$4:$B$100,B6,'BvsC_M6'!$D$4:$D$100) | F6: =SUMIF('AvsB_M1'!$B$4:$B$100,B6,'AvsB_M1'!$E$4:$E$100)+SUMIF('AvsB_M2'!$B$4:$B$100,B6,'AvsB_M2'!$E$4:$E$100)+SUMIF('AvsB_M3'!$B$4:$B$100,B6,'AvsB_M3'!$E$4:$E$100)+SUMIF('AvsB_M4'!$B$4:$B$100,B6,'AvsB_M4'!$E$4:$E$100)+SUMIF('AvsB_M5'!$B$4:$B$100,B6,'AvsB_M5'!$E$4:$E$100)+SUMIF('AvsB_M6'!$B$4:$B$100,B6,'AvsB_M6'!$E$4:$E$100)+SUMIF('CvsD_M1'!$B$4:$B$100,B6,'CvsD_M1'!$E$4:$E$100)+SUMIF('CvsD_M2'!$B$4:$B$100,B6,'CvsD_M2'!$E$4:$E$100)+SUMIF('CvsD_M3'!$B$4:$B$100,B6,'CvsD_M3'!$E$4:$E$100)+SUMIF('CvsD_M4'!$B$4:$B$100,B6,'CvsD_M4'!$E$4:$E$100)+SUMIF('CvsD_M5'!$B$4:$B$100,B6,'CvsD_M5'!$E$4:$E$100)+SUMIF('CvsD_M6'!$B$4:$B$100,B6,'CvsD_M6'!$E$4:$E$100)+SUMIF('AvsC_M1'!$B$4:$B$100,B6,'AvsC_M1'!$E$4:$E$100)+SUMIF('AvsC_M2'!$B$4:$B$100,B6,'AvsC_M2'!$E$4:$E$100)+SUMIF('AvsC_M3'!$B$4:$B$100,B6,'AvsC_M3'!$E$4:$E$100)+SUMIF('AvsC_M4'!$B$4:$B$100,B6,'AvsC_M4'!$E$4:$E$100)+SUMIF('AvsC_M5'!$B$4:$B$100,B6,'AvsC_M5'!$E$4:$E$100)+SUMIF('AvsC_M6'!$B$4:$B$100,B6,'AvsC_M6'!$E$4:$E$100)+SUMIF('BvsD_M1'!$B$4:$B$100,B6,'BvsD_M1'!$E$4:$E$100)+SUMIF('BvsD_M2'!$B$4:$B$100,B6,'BvsD_M2'!$E$4:$E$100)+SUMIF('BvsD_M3'!$B$4:$B$100,B6,'BvsD_M3'!$E$4:$E$100)+SUMIF('BvsD_M4'!$B$4:$B$100,B6,'BvsD_M4'!$E$4:$E$100)+SUMIF('BvsD_M5'!$B$4:$B$100,B6,'BvsD_M5'!$E$4:$E$100)+SUMIF('BvsD_M6'!$B$4:$B$100,B6,'BvsD_M6'!$E$4:$E$100)+SUMIF('AvsD_M1'!$B$4:$B$100,B6,'AvsD_M1'!$E$4:$E$100)+SUMIF('AvsD_M2'!$B$4:$B$100,B6,'AvsD_M2'!$E$4:$E$100)+SUMIF('AvsD_M3'!$B$4:$B$100,B6,'AvsD_M3'!$E$4:$E$100)+SUMIF('AvsD_M4'!$B$4:$B$100,B6,'AvsD_M4'!$E$4:$E$100)+SUMIF('AvsD_M5'!$B$4:$B$100,B6,'AvsD_M5'!$E$4:$E$100)+SUMIF('AvsD_M6'!$B$4:$B$100,B6,'AvsD_M6'!$E$4:$E$100)+SUMIF('BvsC_M1'!$B$4:$B$100,B6,'BvsC_M1'!$E$4:$E$100)+SUMIF('BvsC_M2'!$B$4:$B$100,B6,'BvsC_M2'!$E$4:$E$100)+SUMIF('BvsC_M3'!$B$4:$B$100,B6,'BvsC_M3'!$E$4:$E$100)+SUMIF('BvsC_M4'!$B$4:$B$100,B6,'BvsC_M4'!$E$4:$E$100)+SUMIF('BvsC_M5'!$B$4:$B$100,B6,'BvsC_M5'!$E$4:$E$100)+SUMIF('BvsC_M6'!$B$4:$B$100,B6,'BvsC_M6'!$E$4:$E$100) | G6: =SUMIF('AvsB_M1'!$B$4:$B$100,B6,'AvsB_M1'!$F$4:$F$100)+SUMIF('AvsB_M2'!$B$4:$B$100,B6,'AvsB_M2'!$F$4:$F$100)+SUMIF('AvsB_M3'!$B$4:$B$100,B6,'AvsB_M3'!$F$4:$F$100)+SUMIF('AvsB_M4'!$B$4:$B$100,B6,'AvsB_M4'!$F$4:$F$100)+SUMIF('AvsB_M5'!$B$4:$B$100,B6,'AvsB_M5'!$F$4:$F$100)+SUMIF('AvsB_M6'!$B$4:$B$100,B6,'AvsB_M6'!$F$4:$F$100)+SUMIF('CvsD_M1'!$B$4:$B$100,B6,'CvsD_M1'!$F$4:$F$100)+SUMIF('CvsD_M2'!$B$4:$B$100,B6,'CvsD_M2'!$F$4:$F$100)+SUMIF('CvsD_M3'!$B$4:$B$100,B6,'CvsD_M3'!$F$4:$F$100)+SUMIF('CvsD_M4'!$B$4:$B$100,B6,'CvsD_M4'!$F$4:$F$100)+SUMIF('CvsD_M5'!$B$4:$B$100,B6,'CvsD_M5'!$F$4:$F$100)+SUMIF('CvsD_M6'!$B$4:$B$100,B6,'CvsD_M6'!$F$4:$F$100)+SUMIF('AvsC_M1'!$B$4:$B$100,B6,'AvsC_M1'!$F$4:$F$100)+SUMIF('AvsC_M2'!$B$4:$B$100,B6,'AvsC_M2'!$F$4:$F$100)+SUMIF('AvsC_M3'!$B$4:$B$100,B6,'AvsC_M3'!$F$4:$F$100)+SUMIF('AvsC_M4'!$B$4:$B$100,B6,'AvsC_M4'!$F$4:$F$100)+SUMIF('AvsC_M5'!$B$4:$B$100,B6,'AvsC_M5'!$F$4:$F$100)+SUMIF('AvsC_M6'!$B$4:$B$100,B6,'AvsC_M6'!$F$4:$F$100)+SUMIF('BvsD_M1'!$B$4:$B$100,B6,'BvsD_M1'!$F$4:$F$100)+SUMIF('BvsD_M2'!$B$4:$B$100,B6,'BvsD_M2'!$F$4:$F$100)+SUMIF('BvsD_M3'!$B$4:$B$100,B6,'BvsD_M3'!$F$4:$F$100)+SUMIF('BvsD_M4'!$B$4:$B$100,B6,'BvsD_M4'!$F$4:$F$100)+SUMIF('BvsD_M5'!$B$4:$B$100,B6,'BvsD_M5'!$F$4:$F$100)+SUMIF('BvsD_M6'!$B$4:$B$100,B6,'BvsD_M6'!$F$4:$F$100)+SUMIF('AvsD_M1'!$B$4:$B$100,B6,'AvsD_M1'!$F$4:$F$100)+SUMIF('AvsD_M2'!$B$4:$B$100,B6,'AvsD_M2'!$F$4:$F$100)+SUMIF('AvsD_M3'!$B$4:$B$100,B6,'AvsD_M3'!$F$4:$F$100)+SUMIF('AvsD_M4'!$B$4:$B$100,B6,'AvsD_M4'!$F$4:$F$100)+SUMIF('AvsD_M5'!$B$4:$B$100,B6,'AvsD_M5'!$F$4:$F$100)+SUMIF('AvsD_M6'!$B$4:$B$100,B6,'AvsD_M6'!$F$4:$F$100)+SUMIF('BvsC_M1'!$B$4:$B$100,B6,'BvsC_M1'!$F$4:$F$100)+SUMIF('BvsC_M2'!$B$4:$B$100,B6,'BvsC_M2'!$F$4:$F$100)+SUMIF('BvsC_M3'!$B$4:$B$100,B6,'BvsC_M3'!$F$4:$F$100)+SUMIF('BvsC_M4'!$B$4:$B$100,B6,'BvsC_M4'!$F$4:$F$100)+SUMIF('BvsC_M5'!$B$4:$B$100,B6,'BvsC_M5'!$F$4:$F$100)+SUMIF('BvsC_M6'!$B$4:$B$100,B6,'BvsC_M6'!$F$4:$F$100) | H6: =SUMIF('AvsB_M1'!$B$4:$B$100,B6,'AvsB_M1'!$G$4:$G$100)+SUMIF('AvsB_M2'!$B$4:$B$100,B6,'AvsB_M2'!$G$4:$G$100)+SUMIF('AvsB_M3'!$B$4:$B$100,B6,'AvsB_M3'!$G$4:$G$100)+SUMIF('AvsB_M4'!$B$4:$B$100,B6,'AvsB_M4'!$G$4:$G$100)+SUMIF('AvsB_M5'!$B$4:$B$100,B6,'AvsB_M5'!$G$4:$G$100)+SUMIF('AvsB_M6'!$B$4:$B$100,B6,'AvsB_M6'!$G$4:$G$100)+SUMIF('CvsD_M1'!$B$4:$B$100,B6,'CvsD_M1'!$G$4:$G$100)+SUMIF('CvsD_M2'!$B$4:$B$100,B6,'CvsD_M2'!$G$4:$G$100)+SUMIF('CvsD_M3'!$B$4:$B$100,B6,'CvsD_M3'!$G$4:$G$100)+SUMIF('CvsD_M4'!$B$4:$B$100,B6,'CvsD_M4'!$G$4:$G$100)+SUMIF('CvsD_M5'!$B$4:$B$100,B6,'CvsD_M5'!$G$4:$G$100)+SUMIF('CvsD_M6'!$B$4:$B$100,B6,'CvsD_M6'!$G$4:$G$100)+SUMIF('AvsC_M1'!$B$4:$B$100,B6,'AvsC_M1'!$G$4:$G$100)+SUMIF('AvsC_M2'!$B$4:$B$100,B6,'AvsC_M2'!$G$4:$G$100)+SUMIF('AvsC_M3'!$B$4:$B$100,B6,'AvsC_M3'!$G$4:$G$100)+SUMIF('AvsC_M4'!$B$4:$B$100,B6,'AvsC_M4'!$G$4:$G$100)+SUMIF('AvsC_M5'!$B$4:$B$100,B6,'AvsC_M5'!$G$4:$G$100)+SUMIF('AvsC_M6'!$B$4:$B$100,B6,'AvsC_M6'!$G$4:$G$100)+SUMIF('BvsD_M1'!$B$4:$B$100,B6,'BvsD_M1'!$G$4:$G$100)+SUMIF('BvsD_M2'!$B$4:$B$100,B6,'BvsD_M2'!$G$4:$G$100)+SUMIF('BvsD_M3'!$B$4:$B$100,B6,'BvsD_M3'!$G$4:$G$100)+SUMIF('BvsD_M4'!$B$4:$B$100,B6,'BvsD_M4'!$G$4:$G$100)+SUMIF('BvsD_M5'!$B$4:$B$100,B6,'BvsD_M5'!$G$4:$G$100)+SUMIF('BvsD_M6'!$B$4:$B$100,B6,'BvsD_M6'!$G$4:$G$100)+SUMIF('AvsD_M1'!$B$4:$B$100,B6,'AvsD_M1'!$G$4:$G$100)+SUMIF('AvsD_M2'!$B$4:$B$100,B6,'AvsD_M2'!$G$4:$G$100)+SUMIF('AvsD_M3'!$B$4:$B$100,B6,'AvsD_M3'!$G$4:$G$100)+SUMIF('AvsD_M4'!$B$4:$B$100,B6,'AvsD_M4'!$G$4:$G$100)+SUMIF('AvsD_M5'!$B$4:$B$100,B6,'AvsD_M5'!$G$4:$G$100)+SUMIF('AvsD_M6'!$B$4:$B$100,B6,'AvsD_M6'!$G$4:$G$100)+SUMIF('BvsC_M1'!$B$4:$B$100,B6,'BvsC_M1'!$G$4:$G$100)+SUMIF('BvsC_M2'!$B$4:$B$100,B6,'BvsC_M2'!$G$4:$G$100)+SUMIF('BvsC_M3'!$B$4:$B$100,B6,'BvsC_M3'!$G$4:$G$100)+SUMIF('BvsC_M4'!$B$4:$B$100,B6,'BvsC_M4'!$G$4:$G$100)+SUMIF('BvsC_M5'!$B$4:$B$100,B6,'BvsC_M5'!$G$4:$G$100)+SUMIF('BvsC_M6'!$B$4:$B$100,B6,'BvsC_M6'!$G$4:$G$100) | I6: =SUMIF('AvsB_M1'!$B$4:$B$100,B6,'AvsB_M1'!$H$4:$H$100)+SUMIF('AvsB_M2'!$B$4:$B$100,B6,'AvsB_M2'!$H$4:$H$100)+SUMIF('AvsB_M3'!$B$4:$B$100,B6,'AvsB_M3'!$H$4:$H$100)+SUMIF('AvsB_M4'!$B$4:$B$100,B6,'AvsB_M4'!$H$4:$H$100)+SUMIF('AvsB_M5'!$B$4:$B$100,B6,'AvsB_M5'!$H$4:$H$100)+SUMIF('AvsB_M6'!$B$4:$B$100,B6,'AvsB_M6'!$H$4:$H$100)+SUMIF('CvsD_M1'!$B$4:$B$100,B6,'CvsD_M1'!$H$4:$H$100)+SUMIF('CvsD_M2'!$B$4:$B$100,B6,'CvsD_M2'!$H$4:$H$100)+SUMIF('CvsD_M3'!$B$4:$B$100,B6,'CvsD_M3'!$H$4:$H$100)+SUMIF('CvsD_M4'!$B$4:$B$100,B6,'CvsD_M4'!$H$4:$H$100)+SUMIF('CvsD_M5'!$B$4:$B$100,B6,'CvsD_M5'!$H$4:$H$100)+SUMIF('CvsD_M6'!$B$4:$B$100,B6,'CvsD_M6'!$H$4:$H$100)+SUMIF('AvsC_M1'!$B$4:$B$100,B6,'AvsC_M1'!$H$4:$H$100)+SUMIF('AvsC_M2'!$B$4:$B$100,B6,'AvsC_M2'!$H$4:$H$100)+SUMIF('AvsC_M3'!$B$4:$B$100,B6,'AvsC_M3'!$H$4:$H$100)+SUMIF('AvsC_M4'!$B$4:$B$100,B6,'AvsC_M4'!$H$4:$H$100)+SUMIF('AvsC_M5'!$B$4:$B$100,B6,'AvsC_M5'!$H$4:$H$100)+SUMIF('AvsC_M6'!$B$4:$B$100,B6,'AvsC_M6'!$H$4:$H$100)+SUMIF('BvsD_M1'!$B$4:$B$100,B6,'BvsD_M1'!$H$4:$H$100)+SUMIF('BvsD_M2'!$B$4:$B$100,B6,'BvsD_M2'!$H$4:$H$100)+SUMIF('BvsD_M3'!$B$4:$B$100,B6,'BvsD_M3'!$H$4:$H$100)+SUMIF('BvsD_M4'!$B$4:$B$100,B6,'BvsD_M4'!$H$4:$H$100)+SUMIF('BvsD_M5'!$B$4:$B$100,B6,'BvsD_M5'!$H$4:$H$100)+SUMIF('BvsD_M6'!$B$4:$B$100,B6,'BvsD_M6'!$H$4:$H$100)+SUMIF('AvsD_M1'!$B$4:$B$100,B6,'AvsD_M1'!$H$4:$H$100)+SUMIF('AvsD_M2'!$B$4:$B$100,B6,'AvsD_M2'!$H$4:$H$100)+SUMIF('AvsD_M3'!$B$4:$B$100,B6,'AvsD_M3'!$H$4:$H$100)+SUMIF('AvsD_M4'!$B$4:$B$100,B6,'AvsD_M4'!$H$4:$H$100)+SUMIF('AvsD_M5'!$B$4:$B$100,B6,'AvsD_M5'!$H$4:$H$100)+SUMIF('AvsD_M6'!$B$4:$B$100,B6,'AvsD_M6'!$H$4:$H$100)+SUMIF('BvsC_M1'!$B$4:$B$100,B6,'BvsC_M1'!$H$4:$H$100)+SUMIF('BvsC_M2'!$B$4:$B$100,B6,'BvsC_M2'!$H$4:$H$100)+SUMIF('BvsC_M3'!$B$4:$B$100,B6,'BvsC_M3'!$H$4:$H$100)+SUMIF('BvsC_M4'!$B$4:$B$100,B6,'BvsC_M4'!$H$4:$H$100)+SUMIF('BvsC_M5'!$B$4:$B$100,B6,'BvsC_M5'!$H$4:$H$100)+SUMIF('BvsC_M6'!$B$4:$B$100,B6,'BvsC_M6'!$H$4:$H$100) | J6: =SUMIF('AvsB_M1'!$B$4:$B$100,B6,'AvsB_M1'!$I$4:$I$100)+SUMIF('AvsB_M2'!$B$4:$B$100,B6,'AvsB_M2'!$I$4:$I$100)+SUMIF('AvsB_M3'!$B$4:$B$100,B6,'AvsB_M3'!$I$4:$I$100)+SUMIF('AvsB_M4'!$B$4:$B$100,B6,'AvsB_M4'!$I$4:$I$100)+SUMIF('AvsB_M5'!$B$4:$B$100,B6,'AvsB_M5'!$I$4:$I$100)+SUMIF('AvsB_M6'!$B$4:$B$100,B6,'AvsB_M6'!$I$4:$I$100)+SUMIF('CvsD_M1'!$B$4:$B$100,B6,'CvsD_M1'!$I$4:$I$100)+SUMIF('CvsD_M2'!$B$4:$B$100,B6,'CvsD_M2'!$I$4:$I$100)+SUMIF('CvsD_M3'!$B$4:$B$100,B6,'CvsD_M3'!$I$4:$I$100)+SUMIF('CvsD_M4'!$B$4:$B$100,B6,'CvsD_M4'!$I$4:$I$100)+SUMIF('CvsD_M5'!$B$4:$B$100,B6,'CvsD_M5'!$I$4:$I$100)+SUMIF('CvsD_M6'!$B$4:$B$100,B6,'CvsD_M6'!$I$4:$I$100)+SUMIF('AvsC_M1'!$B$4:$B$100,B6,'AvsC_M1'!$I$4:$I$100)+SUMIF('AvsC_M2'!$B$4:$B$100,B6,'AvsC_M2'!$I$4:$I$100)+SUMIF('AvsC_M3'!$B$4:$B$100,B6,'AvsC_M3'!$I$4:$I$100)+SUMIF('AvsC_M4'!$B$4:$B$100,B6,'AvsC_M4'!$I$4:$I$100)+SUMIF('AvsC_M5'!$B$4:$B$100,B6,'AvsC_M5'!$I$4:$I$100)+SUMIF('AvsC_M6'!$B$4:$B$100,B6,'AvsC_M6'!$I$4:$I$100)+SUMIF('BvsD_M1'!$B$4:$B$100,B6,'BvsD_M1'!$I$4:$I$100)+SUMIF('BvsD_M2'!$B$4:$B$100,B6,'BvsD_M2'!$I$4:$I$100)+SUMIF('BvsD_M3'!$B$4:$B$100,B6,'BvsD_M3'!$I$4:$I$100)+SUMIF('BvsD_M4'!$B$4:$B$100,B6,'BvsD_M4'!$I$4:$I$100)+SUMIF('BvsD_M5'!$B$4:$B$100,B6,'BvsD_M5'!$I$4:$I$100)+SUMIF('BvsD_M6'!$B$4:$B$100,B6,'BvsD_M6'!$I$4:$I$100)+SUMIF('AvsD_M1'!$B$4:$B$100,B6,'AvsD_M1'!$I$4:$I$100)+SUMIF('AvsD_M2'!$B$4:$B$100,B6,'AvsD_M2'!$I$4:$I$100)+SUMIF('AvsD_M3'!$B$4:$B$100,B6,'AvsD_M3'!$I$4:$I$100)+SUMIF('AvsD_M4'!$B$4:$B$100,B6,'AvsD_M4'!$I$4:$I$100)+SUMIF('AvsD_M5'!$B$4:$B$100,B6,'AvsD_M5'!$I$4:$I$100)+SUMIF('AvsD_M6'!$B$4:$B$100,B6,'AvsD_M6'!$I$4:$I$100)+SUMIF('BvsC_M1'!$B$4:$B$100,B6,'BvsC_M1'!$I$4:$I$100)+SUMIF('BvsC_M2'!$B$4:$B$100,B6,'BvsC_M2'!$I$4:$I$100)+SUMIF('BvsC_M3'!$B$4:$B$100,B6,'BvsC_M3'!$I$4:$I$100)+SUMIF('BvsC_M4'!$B$4:$B$100,B6,'BvsC_M4'!$I$4:$I$100)+SUMIF('BvsC_M5'!$B$4:$B$100,B6,'BvsC_M5'!$I$4:$I$100)+SUMIF('BvsC_M6'!$B$4:$B$100,B6,'BvsC_M6'!$I$4:$I$100)
